Workbook
Name Domain_List: Variables!$C$2:$C$15
Name Incident: Variables!$S$2:$S$26
Name Incident_PR: Variables!$I$2:$I$5
Name OpCo_List: Variables!$A$2:$A$4
Name P_Ticket: Variables!$W$2:$W$26
Name P_Ticket_PR: Variables!$M$2:$M$4
Name Queue_List: Variables!$E$2:$E$42
Name Resolution_List: Variables!$Q$2:$Q$5
Name RFS: Variables!$U$2:$U$13
Name RFS_PR: Variables!$K$2:$K$2
Name Status_List: Variables!$O$2:$O$5
Name SubCategory: Variables!$Y$2:$Y$34
Name Type_List: Variables!$G$2:$G$4
Name UKBankHolidays: Variables!$A$13:$A$21

Sheet MSR
A1: Date Picker | B1: 46235 | C1: 46265
A3: Queue Name | B3: Op Co | C3: Domain | D3: P1 Raised | E3: P1 Actioned | F3: P1 Backlogs | G3: P2 Raised | H3: P2 Actioned | I3: P2 Backlogs | J3: P3 Raised | K3: P3 Actioned | L3: P3 Backlogs | M3: P4 Raised | N3: P4 Actioned | O3: P4 Backlogs | P3: RFS Raised | Q3: RFS Actioned | R3: RFS Backlogs | S3: P_Ticket Raised | T3: P_Ticket Actioned | U3: Changes Implemented | V3: Changes Successful | W3: High P_Ticket Raised | X3: High P_Ticket Actioned
A4: APPSUP_SIPLIVE APPSUP_SIPENVHEALTH APPSUP_SIPTOOLS APPSUP_TTPTESTLAB APPSUP_DEVICESLIVE | B4: BA | C4: SIP | D4: =COUNTIFS( SIP!$D:$D,"Incident", SIP!$G:$G,1, SIP!$C:$C,"SIP", SIP!$U:$U,"NO", SIP!$L:$L,">="&$B$1, SIP!$L:$L,"<"&$C$1+1 ) -> 0 | E4: =SUM( COUNTIFS( SIP!$D:$D,"Incident", SIP!$G:$G,1, SIP!$C:$C,"SIP", SIP!$I:$I,"Closed", SIP!$U:$U,"NO", SIP!$N:$N,">="&$B$1, SIP!$N:$N,"<"&$C$1+1 ), COUNTIFS( SIP!$D:$D,"Incident", SIP!$G:$G,1, SIP!$C:$C,"SIP", SIP!$I:$I,"Triaged", SIP!$U:$U,"NO", SIP!$N:$N,">="&$B$1, SIP!$N:$N,"<"&$C$1+1 ) ) -> 0 | F4: =COUNTIFS( SIP!$C:$C,"SIP", SIP!$D:$D,"Incident", SIP!$G:$G,1, SIP!$U:$U,"<>YES", SIP!$K:$K,"<"&$B$1, SIP!$N:$N,"" ) + COUNTIFS( SIP!$C:$C,"SIP", SIP!$D:$D,"Incident", SIP!$G:$G,1, SIP!$U:$U,"<>YES", SIP!$K:$K,"<"&$B$1, SIP!$N:$N,">="&$B$1 ) + COUNTIFS( SIP!$C:$C,"SIP", SIP!$D:$D,"Incident", SIP!$G:$G,1, SIP!$U:$U,"<>YES", SIP!$K:$K,">="&$B$1, SIP!$K:$K,"<"&$C$1+1 ) - COUNTIFS( SIP!$C:$C,"SIP", SIP!$D:$D,"Incident", SIP!$G:$G,1, SIP!$U:$U,"<>YES", SIP!$I:$I,"Closed", SIP!$N:$N,">="&$B$1, SIP!$N:$N,"<"&$C$1+1 ) - COUNTIFS( SIP!$C:$C,"SIP", SIP!$D:$D,"Incident", SIP!$G:$G,1, SIP!$U:$U,"<>YES", SIP!$I:$I,"Triaged", SIP!$N:$N,">="&$B$1, SIP!$N:$N,"<"&$C$1+1 ) -> 0 | G4: =COUNTIFS( SIP!$D:$D,"Incident", SIP!$G:$G,2, SIP!$C:$C,"SIP", SIP!$U:$U,"NO", SIP!$L:$L,">="&$B$1, SIP!$L:$L,"<"&$C$1+1 ) -> 0 | H4: =SUM( COUNTIFS( SIP!$D:$D,"Incident", SIP!$G:$G,2, SIP!$C:$C,"SIP", SIP!$I:$I,"Closed", SIP!$U:$U,"NO", SIP!$N:$N,">="&$B$1, SIP!$N:$N,"<"&$C$1+1 ), COUNTIFS( SIP!$D:$D,"Incident", SIP!$G:$G,2, SIP!$C:$C,"SIP", SIP!$I:$I,"Triaged", SIP!$U:$U,"NO", SIP!$N:$N,">="&$B$1, SIP!$N:$N,"<"&$C$1+1 ) ) -> 0 | I4: =COUNTIFS( SIP!$C:$C,"SIP", SIP!$D:$D,"Incident", SIP!$G:$G,2, SIP!$U:$U,"<>YES", SIP!$K:$K,"<"&$B$1, SIP!$N:$N,"" ) + COUNTIFS( SIP!$C:$C,"SIP", SIP!$D:$D,"Incident", SIP!$G:$G,2, SIP!$U:$U,"<>YES", SIP!$K:$K,"<"&$B$1, SIP!$N:$N,">="&$B$1 ) + COUNTIFS( SIP!$C:$C,"SIP", SIP!$D:$D,"Incident", SIP!$G:$G,2, SIP!$U:$U,"<>YES", SIP!$K:$K,">="&$B$1, SIP!$K:$K,"<"&$C$1+1 ) - COUNTIFS( SIP!$C:$C,"SIP", SIP!$D:$D,"Incident", SIP!$G:$G,2, SIP!$U:$U,"<>YES", SIP!$I:$I,"Closed", SIP!$N:$N,">="&$B$1, SIP!$N:$N,"<"&$C$1+1 ) - COUNTIFS( SIP!$C:$C,"SIP", SIP!$D:$D,"Incident", SIP!$G:$G,2, SIP!$U:$U,"<>YES", SIP!$I:$I,"Triaged", SIP!$N:$N,">="&$B$1, SIP!$N:$N,"<"&$C$1+1 ) -> 0 | J4: =COUNTIFS( SIP!$D:$D,"Incident", SIP!$G:$G,3, SIP!$C:$C,"SIP", SIP!$U:$U,"NO", SIP!$L:$L,">="&$B$1, SIP!$L:$L,"<"&$C$1+1 ) -> 0 | K4: =SUM( COUNTIFS( SIP!$D:$D,"Incident", SIP!$G:$G,3, SIP!$C:$C,"SIP", SIP!$I:$I,"Closed", SIP!$U:$U,"NO", SIP!$N:$N,">="&$B$1, SIP!$N:$N,"<"&$C$1+1 ), COUNTIFS( SIP!$D:$D,"Incident", SIP!$G:$G,3, SIP!$C:$C,"SIP", SIP!$I:$I,"Triaged", SIP!$U:$U,"NO", SIP!$N:$N,">="&$B$1, SIP!$N:$N,"<"&$C$1+1 ) ) -> 0 | L4: =COUNTIFS( SIP!$C:$C,"SIP", SIP!$D:$D,"Incident", SIP!$G:$G,3, SIP!$U:$U,"<>YES", SIP!$K:$K,"<"&$B$1, SIP!$N:$N,"" ) + COUNTIFS( SIP!$C:$C,"SIP", SIP!$D:$D,"Incident", SIP!$G:$G,3, SIP!$U:$U,"<>YES", SIP!$K:$K,"<"&$B$1, SIP!$N:$N,">="&$B$1 ) + COUNTIFS( SIP!$C:$C,"SIP", SIP!$D:$D,"Incident", SIP!$G:$G,3, SIP!$U:$U,"<>YES", SIP!$K:$K,">="&$B$1, SIP!$K:$K,"<"&$C$1+1 ) - COUNTIFS( SIP!$C:$C,"SIP", SIP!$D:$D,"Incident", SIP!$G:$G,3, SIP!$U:$U,"<>YES", SIP!$I:$I,"Closed", SIP!$N:$N,">="&$B$1, SIP!$N:$N,"<"&$C$1+1 ) - COUNTIFS( SIP!$C:$C,"SIP", SIP!$D:$D,"Incident", SIP!$G:$G,3, SIP!$U:$U,"<>YES", SIP!$I:$I,"Triaged", SIP!$N:$N,">="&$B$1, SIP!$N:$N,"<"&$C$1+1 ) -> 211 | M4: =COUNTIFS( SIP!$D:$D,"Incident", SIP!$G:$G,4, SIP!$C:$C,"SIP", SIP!$U:$U,"NO", SIP!$L:$L,">="&$B$1, SIP!$L:$L,"<"&$C$1+1 ) -> 0 | N4: =SUM( COUNTIFS( SIP!$D:$D,"Incident", SIP!$G:$G,4, SIP!$C:$C,"SIP", SIP!$I:$I,"Closed", SIP!$U:$U,"NO", SIP!$N:$N,">="&$B$1, SIP!$N:$N,"<"&$C$1+1 ), COUNTIFS( SIP!$D:$D,"Incident", SIP!$G:$G,4, SIP!$C:$C,"SIP", SIP!$I:$I,"Triaged", SIP!$U:$U,"NO", SIP!$N:$N,">="&$B$1, SIP!$N:$N,"<"&$C$1+1 ) ) -> 0 | O4: =COUNTIFS( SIP!$C:$C,"SIP", SIP!$D:$D,"Incident", SIP!$G:$G,4, SIP!$U:$U,"<>YES", SIP!$K:$K,"<"&$B$1, SIP!$N:$N,"" ) + COUNTIFS( SIP!$C:$C,"SIP", SIP!$D:$D,"Incident", SIP!$G:$G,4, SIP!$U:$U,"<>YES", SIP!$K:$K,"<"&$B$1, SIP!$N:$N,">="&$B$1 ) + COUNTIFS( SIP!$C:$C,"SIP", SIP!$D:$D,"Incident", SIP!$G:$G,4, SIP!$U:$U,"<>YES", SIP!$K:$K,">="&$B$1, SIP!$K:$K,"<"&$C$1+1 ) - COUNTIFS( SIP!$C:$C,"SIP", SIP!$D:$D,"Incident", SIP!$G:$G,4, SIP!$U:$U,"<>YES", SIP!$I:$I,"Closed", SIP!$N:$N,">="&$B$1, SIP!$N:$N,"<"&$C$1+1 ) - COUNTIFS( SIP!$C:$C,"SIP", SIP!$D:$D,"Incident", SIP!$G:$G,4, SIP!$U:$U,"<>YES", SIP!$I:$I,"Triaged", SIP!$N:$N,">="&$B$1, SIP!$N:$N,"<"&$C$1+1 ) -> 67 | P4: =COUNTIFS( SIP!$D:$D,"RFS", SIP!$C:$C,"SIP", SIP!$U:$U,"NO", SIP!$L:$L,">="&$B$1, SIP!$L:$L,"<"&$C$1+1 ) -> 0 | Q4: =SUM( COUNTIFS( SIP!$D:$D,"RFS", SIP!$C:$C,"SIP", SIP!$I:$I,"Closed", SIP!$U:$U,"NO", SIP!$N:$N,">="&$B$1, SIP!$N:$N,"<"&$C$1+1 ), COUNTIFS( SIP!$D:$D,"RFS", SIP!$C:$C,"SIP", SIP!$I:$I,"Triaged", SIP!$U:$U,"NO", SIP!$N:$N,">="&$B$1, SIP!$N:$N,"<"&$C$1+1 ) ) -> 0 | R4: =COUNTIFS( SIP!$D:$D,"RFS", SIP!$C:$C,"SIP", SIP!$U:$U,"<>YES", SIP!$K:$K,"<"&$B$1, SIP!$N:$N,"" ) + COUNTIFS( SIP!$D:$D,"RFS", SIP!$C:$C,"SIP", SIP!$U:$U,"<>YES", SIP!$K:$K,"<"&$B$1, SIP!$N:$N,">="&$B$1 ) + COUNTIFS( SIP!$D:$D,"RFS", SIP!$C:$C,"SIP", SIP!$U:$U,"<>YES", SIP!$K:$K,">="&$B$1, SIP!$K:$K,"<"&$C$1+1 ) - COUNTIFS( SIP!$D:$D,"RFS", SIP!$C:$C,"SIP", SIP!$I:$I,"Closed", SIP!$U:$U,"<>YES", SIP!$N:$N,">="&$B$1, SIP!$N:$N,"<"&$C$1+1 ) - COUNTIFS( SIP!$D:$D,"RFS", SIP!$C:$C,"SIP", SIP!$I:$I,"Triaged", SIP!$U:$U,"<>YES", SIP!$N:$N,">="&$B$1, SIP!$N:$N,"<"&$C$1+1 ) -> 172 | S4: =SUM( COUNTIFS( SIP!$D:$D,"P_Ticket", SIP!$G:$G,"Low", SIP!$C:$C,"SIP", SIP!$U:$U,"NO", SIP!$L:$L,">="&$B$1, SIP!$L:$L,"<"&$C$1+1 ), COUNTIFS( SIP!$D:$D,"P_Ticket", SIP!$G:$G,"Medium", SIP!$C:$C,"SIP", SIP!$U:$U,"NO", SIP!$L:$L,">="&$B$1, SIP!$L:$L,"<"&$C$1+1 ), COUNTIFS( SIP!$D:$D,"P_Ticket", SIP!$G:$G,"High", SIP!$C:$C,"SIP", SIP!$U:$U,"NO", SIP!$L:$L,">="&$B$1, SIP!$L:$L,"<"&$C$1+1 ) ) -> 0 | T4: =SUM(COUNTIFS(SIP!$D:$D,"P_Ticket",SIP!$G:$G,"Low",SIP!$C:$C,"SIP",SIP!$I:$I,"Closed",SIP!$U:$U,"NO",SIP!$N:$N,"<"&$C$1+1,SIP!$N:$N,">="&$B$1),COUNTIFS(SIP!$D:$D,"P_Ticket",SIP!$G:$G,"Medium",SIP!$C:$C,"SIP",SIP!$I:$I,"Closed",SIP!$U:$U,"NO",SIP!$N:$N,"<"&$C$1+1,SIP!$N:$N,">="&$B$1),COUNTIFS(SIP!$D:$D,"P_Ticket",SIP!$G:$G,"High",SIP!$C:$C,"SIP",SIP!$I:$I,"Closed",SIP!$U:$U,"NO",SIP!$N:$N,"<"&$C$1+1,SIP!$N:$N,">="&$B$1),COUNTIFS(SIP!$D:$D,"P_Ticket",SIP!$G:$G,"Low",SIP!$C:$C,"SIP",SIP!$I:$I,"Triaged",SIP!$U:$U,"NO",SIP!$N:$N,"<"&$C$1+1,SIP!$N:$N,">="&$B$1),COUNTIFS(SIP!$D:$D,"P_Ticket",SIP!$G:$G,"Medium",SIP!$C:$C,"SIP",SIP!$I:$I,"Triaged",SIP!$U:$U,"NO",SIP!$N:$N,"<"&$C$1+1,SIP!$N:$N,">="&$B$1),COUNTIFS(SIP!$D:$D,"P_Ticket",SIP!$G:$G,"High",SIP!$C:$C,"SIP",SIP!$I:$I,"Triaged",SIP!$U:$U,"NO",SIP!$N:$N,"<"&$C$1+1,SIP!$N:$N,">="&$B$1)) -> 0 | W4: =COUNTIFS( SIP!$D:$D,"P_Ticket", SIP!$G:$G,"High", SIP!$C:$C,"SIP", SIP!$U:$U,"NO", SIP!$L:$L,">="&$B$1, SIP!$L:$L,"<"&$C$1+1 ) -> 0 | X4: =SUM( COUNTIFS( SIP!$D:$D,"P_Ticket", SIP!$C:$C,"SIP", SIP!$G:$G,"High", SIP!$I:$I,"Closed", SIP!$U:$U,"NO", SIP!$N:$N,"<"&$C$1+1, SIP!$N:$N,">="&$B$1 ), COUNTIFS( SIP!$D:$D,"P_Ticket", SIP!$C:$C,"SIP", SIP!$G:$G,"High", SIP!$I:$I,"Triaged", SIP!$U:$U,"NO", SIP!$N:$N,"<"&$C$1+1, SIP!$N:$N,">="&$B$1 ) ) -> 0
A5: APPSUP_SPOMGSV APPSUP_POWERAPPS | B5: BA | C5: SharePoint | D5: =COUNTIFS( 'BA BackOffice'!$D:$D,"Incident", 'BA BackOffice'!$G:$G,1, 'BA BackOffice'!$C:$C,"SharePoint", 'BA BackOffice'!$U:$U,"NO", 'BA BackOffice'!$L:$L,">="&$B$1, 'BA BackOffice'!$L:$L,"<"&$C$1+1 ) -> 0 | E5: =SUM( COUNTIFS( 'BA BackOffice'!$D:$D,"Incident", 'BA BackOffice'!$C:$C,"SharePoint", 'BA BackOffice'!$G:$G,1, 'BA BackOffice'!$I:$I,"Closed", 'BA BackOffice'!$U:$U,"NO", 'BA BackOffice'!$N:$N,">="&$B$1, 'BA BackOffice'!$N:$N,"<"&$C$1+1 ), COUNTIFS( 'BA BackOffice'!$D:$D,"Incident", 'BA BackOffice'!$C:$C,"SharePoint", 'BA BackOffice'!$G:$G,1, 'BA BackOffice'!$I:$I,"Triaged", 'BA BackOffice'!$U:$U,"NO", 'BA BackOffice'!$N:$N,">="&$B$1, 'BA BackOffice'!$N:$N,"<"&$C$1+1 ) ) -> 0 | F5: =COUNTIFS( 'BA BackOffice'!$C:$C,"SharePoint", 'BA BackOffice'!$D:$D,"Incident", 'BA BackOffice'!$G:$G,1, 'BA BackOffice'!$U:$U,"<>YES", 'BA BackOffice'!$K:$K,"<"&$B$1, 'BA BackOffice'!$N:$N,"" ) + COUNTIFS( 'BA BackOffice'!$C:$C,"SharePoint", 'BA BackOffice'!$D:$D,"Incident", 'BA BackOffice'!$G:$G,1, 'BA BackOffice'!$U:$U,"<>YES", 'BA BackOffice'!$K:$K,"<"&$B$1, 'BA BackOffice'!$N:$N,">="&$B$1 ) + COUNTIFS( 'BA BackOffice'!$C:$C,"SharePoint", 'BA BackOffice'!$D:$D,"Incident", 'BA BackOffice'!$G:$G,1, 'BA BackOffice'!$U:$U,"<>YES", 'BA BackOffice'!$K:$K,">="&$B$1, 'BA BackOffice'!$K:$K,"<"&$C$1+1 ) - COUNTIFS( 'BA BackOffice'!$C:$C,"SharePoint", 'BA BackOffice'!$D:$D,"Incident", 'BA BackOffice'!$G:$G,1, 'BA BackOffice'!$U:$U,"<>YES", 'BA BackOffice'!$I:$I,"Closed", 'BA BackOffice'!$N:$N,">="&$B$1, 'BA BackOffice'!$N:$N,"<"&$C$1+1 ) - COUNTIFS( 'BA BackOffice'!$C:$C,"SharePoint", 'BA BackOffice'!$D:$D,"Incident", 'BA BackOffice'!$G:$G,1, 'BA BackOffice'!$U:$U,"<>YES", 'BA BackOffice'!$I:$I,"Triaged", 'BA BackOffice'!$N:$N,">="&$B$1, 'BA BackOffice'!$N:$N,"<"&$C$1+1 ) -> 0 | G5: =COUNTIFS( 'BA BackOffice'!$D:$D,"Incident", 'BA BackOffice'!$G:$G,2, 'BA BackOffice'!$C:$C,"SharePoint", 'BA BackOffice'!$U:$U,"NO", 'BA BackOffice'!$L:$L,">="&$B$1, 'BA BackOffice'!$L:$L,"<"&$C$1+1 ) -> 0 | H5: =SUM( COUNTIFS( 'BA BackOffice'!$D:$D,"Incident", 'BA BackOffice'!$C:$C,"SharePoint", 'BA BackOffice'!$G:$G,2, 'BA BackOffice'!$I:$I,"Closed", 'BA BackOffice'!$U:$U,"NO", 'BA BackOffice'!$N:$N,">="&$B$1, 'BA BackOffice'!$N:$N,"<"&$C$1+1 ), COUNTIFS( 'BA BackOffice'!$D:$D,"Incident", 'BA BackOffice'!$C:$C,"SharePoint", 'BA BackOffice'!$G:$G,2, 'BA BackOffice'!$I:$I,"Triaged", 'BA BackOffice'!$U:$U,"NO", 'BA BackOffice'!$N:$N,">="&$B$1, 'BA BackOffice'!$N:$N,"<"&$C$1+1 ) ) -> 0 | I5: =COUNTIFS( 'BA BackOffice'!$C:$C,"SharePoint", 'BA BackOffice'!$D:$D,"Incident", 'BA BackOffice'!$G:$G,2, 'BA BackOffice'!$U:$U,"<>YES", 'BA BackOffice'!$K:$K,"<"&$B$1, 'BA BackOffice'!$N:$N,"" ) + COUNTIFS( 'BA BackOffice'!$C:$C,"SharePoint", 'BA BackOffice'!$D:$D,"Incident", 'BA BackOffice'!$G:$G,2, 'BA BackOffice'!$U:$U,"<>YES", 'BA BackOffice'!$K:$K,"<"&$B$1, 'BA BackOffice'!$N:$N,">="&$B$1 ) + COUNTIFS( 'BA BackOffice'!$C:$C,"SharePoint", 'BA BackOffice'!$D:$D,"Incident", 'BA BackOffice'!$G:$G,2, 'BA BackOffice'!$U:$U,"<>YES", 'BA BackOffice'!$K:$K,">="&$B$1, 'BA BackOffice'!$K:$K,"<"&$C$1+1 ) - COUNTIFS( 'BA BackOffice'!$C:$C,"SharePoint", 'BA BackOffice'!$D:$D,"Incident", 'BA BackOffice'!$G:$G,2, 'BA BackOffice'!$U:$U,"<>YES", 'BA BackOffice'!$I:$I,"Closed", 'BA BackOffice'!$N:$N,">="&$B$1, 'BA BackOffice'!$N:$N,"<"&$C$1+1 ) - COUNTIFS( 'BA BackOffice'!$C:$C,"SharePoint", 'BA BackOffice'!$D:$D,"Incident", 'BA BackOffice'!$G:$G,2, 'BA BackOffice'!$U:$U,"<>YES", 'BA BackOffice'!$I:$I,"Triaged", 'BA BackOffice'!$N:$N,">="&$B$1, 'BA BackOffice'!$N:$N,"<"&$C$1+1 ) -> 0 | J5: =COUNTIFS( 'BA BackOffice'!$D:$D,"Incident", 'BA BackOffice'!$G:$G,3, 'BA BackOffice'!$C:$C,"SharePoint", 'BA BackOffice'!$U:$U,"NO", 'BA BackOffice'!$L:$L,">="&$B$1, 'BA BackOffice'!$L:$L,"<"&$C$1+1 ) -> 1 | K5: =SUM( COUNTIFS( 'BA BackOffice'!$D:$D,"Incident", 'BA BackOffice'!$C:$C,"SharePoint", 'BA BackOffice'!$G:$G,3, 'BA BackOffice'!$I:$I,"Closed", 'BA BackOffice'!$U:$U,"NO", 'BA BackOffice'!$N:$N,">="&$B$1, 'BA BackOffice'!$N:$N,"<"&$C$1+1 ), COUNTIFS( 'BA BackOffice'!$D:$D,"Incident", 'BA BackOffice'!$C:$C,"SharePoint", 'BA BackOffice'!$G:$G,3, 'BA BackOffice'!$I:$I,"Triaged", 'BA BackOffice'!$U:$U,"NO", 'BA BackOffice'!$N:$N,">="&$B$1, 'BA BackOffice'!$N:$N,"<"&$C$1+1 ) ) -> 1 | L5: =COUNTIFS( 'BA BackOffice'!$C:$C,"SharePoint", 'BA BackOffice'!$D:$D,"Incident", 'BA BackOffice'!$G:$G,3, 'BA BackOffice'!$U:$U,"<>YES", 'BA BackOffice'!$K:$K,"<"&$B$1, 'BA BackOffice'!$N:$N,"" ) + COUNTIFS( 'BA BackOffice'!$C:$C,"SharePoint", 'BA BackOffice'!$D:$D,"Incident", 'BA BackOffice'!$G:$G,3, 'BA BackOffice'!$U:$U,"<>YES", 'BA BackOffice'!$K:$K,"<"&$B$1, 'BA BackOffice'!$N:$N,">="&$B$1 ) + COUNTIFS( 'BA BackOffice'!$C:$C,"SharePoint", 'BA BackOffice'!$D:$D,"Incident", 'BA BackOffice'!$G:$G,3, 'BA BackOffice'!$U:$U,"<>YES", 'BA BackOffice'!$K:$K,">="&$B$1, 'BA BackOffice'!$K:$K,"<"&$C$1+1 ) - COUNTIFS( 'BA BackOffice'!$C:$C,"SharePoint", 'BA BackOffice'!$D:$D,"Incident", 'BA BackOffice'!$G:$G,3, 'BA BackOffice'!$U:$U,"<>YES", 'BA BackOffice'!$I:$I,"Closed", 'BA BackOffice'!$N:$N,">="&$B$1, 'BA BackOffice'!$N:$N,"<"&$C$1+1 ) - COUNTIFS( 'BA BackOffice'!$C:$C,"SharePoint", 'BA BackOffice'!$D:$D,"Incident", 'BA BackOffice'!$G:$G,3, 'BA BackOffice'!$U:$U,"<>YES", 'BA BackOffice'!$I:$I,"Triaged", 'BA BackOffice'!$N:$N,">="&$B$1, 'BA BackOffice'!$N:$N,"<"&$C$1+1 ) -> 0 | M5: =COUNTIFS( 'BA BackOffice'!$D:$D,"Incident", 'BA BackOffice'!$G:$G,4, 'BA BackOffice'!$C:$C,"SharePoint", 'BA BackOffice'!$U:$U,"NO", 'BA BackOffice'!$L:$L,">="&$B$1, 'BA BackOffice'!$L:$L,"<"&$C$1+1 ) -> 6 | N5: =SUM( COUNTIFS( 'BA BackOffice'!$D:$D,"Incident", 'BA BackOffice'!$C:$C,"SharePoint", 'BA BackOffice'!$G:$G,4, 'BA BackOffice'!$I:$I,"Closed", 'BA BackOffice'!$U:$U,"NO", 'BA BackOffice'!$N:$N,">="&$B$1, 'BA BackOffice'!$N:$N,"<"&$C$1+1 ), COUNTIFS( 'BA BackOffice'!$D:$D,"Incident", 'BA BackOffice'!$C:$C,"SharePoint", 'BA BackOffice'!$G:$G,4, 'BA BackOffice'!$I:$I,"Triaged", 'BA BackOffice'!$U:$U,"NO", 'BA BackOffice'!$N:$N,">="&$B$1, 'BA BackOffice'!$N:$N,"<"&$C$1+1 ) ) -> 6 | O5: =COUNTIFS( 'BA BackOffice'!$C:$C,"SharePoint", 'BA BackOffice'!$D:$D,"Incident", 'BA BackOffice'!$G:$G,4, 'BA BackOffice'!$U:$U,"<>YES", 'BA BackOffice'!$K:$K,"<"&$B$1, 'BA BackOffice'!$N:$N,"" ) + COUNTIFS( 'BA BackOffice'!$C:$C,"SharePoint", 'BA BackOffice'!$D:$D,"Incident", 'BA BackOffice'!$G:$G,4, 'BA BackOffice'!$U:$U,"<>YES", 'BA BackOffice'!$K:$K,"<"&$B$1, 'BA BackOffice'!$N:$N,">="&$B$1 ) + COUNTIFS( 'BA BackOffice'!$C:$C,"SharePoint", 'BA BackOffice'!$D:$D,"Incident", 'BA BackOffice'!$G:$G,4, 'BA BackOffice'!$U:$U,"<>YES", 'BA BackOffice'!$K:$K,">="&$B$1, 'BA BackOffice'!$K:$K,"<"&$C$1+1 ) - COUNTIFS( 'BA BackOffice'!$C:$C,"SharePoint", 'BA BackOffice'!$D:$D,"Incident", 'BA BackOffice'!$G:$G,4, 'BA BackOffice'!$U:$U,"<>YES", 'BA BackOffice'!$I:$I,"Closed", 'BA BackOffice'!$N:$N,">="&$B$1, 'BA BackOffice'!$N:$N,"<"&$C$1+1 ) - COUNTIFS( 'BA BackOffice'!$C:$C,"SharePoint", 'BA BackOffice'!$D:$D,"Incident", 'BA BackOffice'!$G:$G,4, 'BA BackOffice'!$U:$U,"<>YES", 'BA BackOffice'!$I:$I,"Triaged", 'BA BackOffice'!$N:$N,">="&$B$1, 'BA BackOffice'!$N:$N,"<"&$C$1+1 ) -> 1 | P5: =COUNTIFS( 'BA BackOffice'!$D:$D,"RFS", 'BA BackOffice'!$C:$C,"SharePoint", 'BA BackOffice'!$U:$U,"No", 'BA BackOffice'!$L:$L,">="&$B$1, 'BA BackOffice'!$L:$L,"<"&$C$1+1 ) -> 0 | Q5: =SUM( COUNTIFS( 'BA BackOffice'!$D:$D,"RFS", 'BA BackOffice'!$C:$C,"SharePoint", 'BA BackOffice'!$I:$I,"Closed", 'BA BackOffice'!$U:$U,"NO", 'BA BackOffice'!$N:$N,">="&$B$1, 'BA BackOffice'!$N:$N,"<"&$C$1+1 ), COUNTIFS( 'BA BackOffice'!$D:$D,"RFS", 'BA BackOffice'!$C:$C,"SharePoint", 'BA BackOffice'!$I:$I,"Triaged", 'BA BackOffice'!$U:$U,"NO", 'BA BackOffice'!$N:$N,">="&$B$1, 'BA BackOffice'!$N:$N,"<"&$C$1+1 ) ) -> 7 | R5: =COUNTIFS( 'BA BackOffice'!$D:$D,"RFS", 'BA BackOffice'!$C:$C,"SharePoint", 'BA BackOffice'!$U:$U,"<>YES", 'BA BackOffice'!$K:$K,"<"&$B$1, 'BA BackOffice'!$N:$N,"" ) + COUNTIFS( 'BA BackOffice'!$D:$D,"RFS", 'BA BackOffice'!$C:$C,"SharePoint", 'BA BackOffice'!$U:$U,"<>YES", 'BA BackOffice'!$K:$K,"<"&$B$1, 'BA BackOffice'!$N:$N,">="&$B$1 ) + COUNTIFS( 'BA BackOffice'!$D:$D,"RFS", 'BA BackOffice'!$C:$C,"SharePoint", 'BA BackOffice'!$U:$U,"<>YES", 'BA BackOffice'!$K:$K,">="&$B$1, 'BA BackOffice'!$K:$K,"<"&$C$1+1 ) - COUNTIFS( 'BA BackOffice'!$D:$D,"RFS", 'BA BackOffice'!$C:$C,"SharePoint", 'BA BackOffice'!$I:$I,"Closed", 'BA BackOffice'!$U:$U,"<>YES", 'BA BackOffice'!$N:$N,">="&$B$1, 'BA BackOffice'!$N:$N,"<"&$C$1+1 ) - COUNTIFS( 'BA BackOffice'!$D:$D,"RFS", 'BA BackOffice'!$C:$C,"SharePoint", 'BA BackOffice'!$I:$I,"Triaged", 'BA BackOffice'!$U:$U,"<>YES", 'BA BackOffice'!$N:$N,">="&$B$1, 'BA BackOffice'!$N:$N,"<"&$C$1+1 ) -> 3 | S5: =SUM( COUNTIFS( 'BA BackOffice'!$D:$D,"P_Ticket", 'BA BackOffice'!$G:$G,"Low", 'BA BackOffice'!$C:$C,"SharePoint", 'BA BackOffice'!$U:$U,"NO", 'BA BackOffice'!$L:$L,">="&$B$1, 'BA BackOffice'!$L:$L,"<"&$C$1+1 ), COUNTIFS( 'BA BackOffice'!$D:$D,"P_Ticket", 'BA BackOffice'!$G:$G,"Medium", 'BA BackOffice'!$C:$C,"SharePoint", 'BA BackOffice'!$U:$U,"NO", 'BA BackOffice'!$L:$L,">="&$B$1, 'BA BackOffice'!$L:$L,"<"&$C$1+1 ), COUNTIFS( 'BA BackOffice'!$D:$D,"P_Ticket", 'BA BackOffice'!$G:$G,"High", 'BA BackOffice'!$C:$C,"SharePoint", 'BA BackOffice'!$U:$U,"NO", 'BA BackOffice'!$L:$L,">="&$B$1, 'BA BackOffice'!$L:$L,"<"&$C$1+1 ) ) -> 0 | T5: =SUM(COUNTIFS('BA BackOffice'!$D:$D,"P_Ticket",'BA BackOffice'!$C:$C,"SharePoint",'BA BackOffice'!$G:$G,"Low",'BA BackOffice'!$I:$I,"Closed",'BA BackOffice'!$U:$U,"NO",'BA BackOffice'!$N:$N,"<"&$C$1+1,'BA BackOffice'!$N:$N,">="&$B$1),COUNTIFS('BA BackOffice'!$D:$D,"P_Ticket",'BA BackOffice'!$C:$C,"SharePoint",'BA BackOffice'!$G:$G,"Medium",'BA BackOffice'!$I:$I,"Closed",'BA BackOffice'!$U:$U,"NO",'BA BackOffice'!$N:$N,"<"&$C$1+1,'BA BackOffice'!$N:$N,">="&$B$1),COUNTIFS('BA BackOffice'!$D:$D,"P_Ticket",'BA BackOffice'!$C:$C,"SharePoint",'BA BackOffice'!$G:$G,"High",'BA BackOffice'!$I:$I,"Closed",'BA BackOffice'!$U:$U,"NO",'BA BackOffice'!$N:$N,"<"&$C$1+1,'BA BackOffice'!$N:$N,">="&$B$1),COUNTIFS('BA BackOffice'!$D:$D,"P_Ticket",'BA BackOffice'!$C:$C,"SharePoint",'BA BackOffice'!$G:$G,"Low",'BA BackOffice'!$I:$I,"Triaged",'BA BackOffice'!$U:$U,"NO",'BA BackOffice'!$N:$N,"<"&$C$1+1,'BA BackOffice'!$N:$N,">="&$B$1),COUNTIFS('BA BackOffice'!$D:$D,"P_Ticket",'BA BackOffice'!$C:$C,"SharePoint",'BA BackOffice'!$G:$G,"Medium",'BA BackOffice'!$I:$I,"Triaged",'BA BackOffice'!$U:$U,"NO",'BA BackOffice'!$N:$N,"<"&$C$1+1,'BA BackOffice'!$N:$N,">="&$B$1),COUNTIFS('BA BackOffice'!$D:$D,"P_Ticket",'BA BackOffice'!$C:$C,"SharePoint",'BA BackOffice'!$G:$G,"High",'BA BackOffice'!$I:$I,"Triaged",'BA BackOffice'!$U:$U,"NO",'BA BackOffice'!$N:$N,"<"&$C$1+1,'BA BackOffice'!$N:$N,">="&$B$1)) -> 0 | W5: =COUNTIFS( 'BA BackOffice'!$D:$D,"P_Ticket", 'BA BackOffice'!$G:$G,"High", 'BA BackOffice'!$C:$C,"SharePoint", 'BA BackOffice'!$U:$U,"NO", 'BA BackOffice'!$L:$L,">="&$B$1, 'BA BackOffice'!$L:$L,"<"&$C$1+1 ) -> 0 | X5: =SUM( COUNTIFS( 'BA BackOffice'!$D:$D,"P_Ticket", 'BA BackOffice'!$C:$C,"SharePoint", 'BA BackOffice'!$G:$G,"High", 'BA BackOffice'!$I:$I,"Closed", 'BA BackOffice'!$U:$U,"NO", 'BA BackOffice'!$N:$N,"<"&$C$1+1, 'BA BackOffice'!$N:$N,">="&$B$1 ), COUNTIFS( 'BA BackOffice'!$D:$D,"P_Ticket", 'BA BackOffice'!$C:$C,"SharePoint", 'BA BackOffice'!$G:$G,"High", 'BA BackOffice'!$I:$I,"Triaged", 'BA BackOffice'!$U:$U,"NO", 'BA BackOffice'!$N:$N,"<"&$C$1+1, 'BA BackOffice'!$N:$N,">="&$B$1 ) ) -> 0
A6: APPSUP_APEX | B6: BA | C6: Apex | D6: =COUNTIFS( 'BA BackOffice'!$D:$D,"Incident", 'BA BackOffice'!$G:$G,1, 'BA BackOffice'!$C:$C,"Apex", 'BA BackOffice'!$U:$U,"NO", 'BA BackOffice'!$L:$L,">="&$B$1, 'BA BackOffice'!$L:$L,"<"&$C$1+1 ) -> 0 | E6: =SUM( COUNTIFS( 'BA BackOffice'!$D:$D,"Incident", 'BA BackOffice'!$C:$C,"Apex", 'BA BackOffice'!$G:$G,1, 'BA BackOffice'!$I:$I,"Closed", 'BA BackOffice'!$U:$U,"NO", 'BA BackOffice'!$N:$N,">="&$B$1, 'BA BackOffice'!$N:$N,"<"&$C$1+1 ), COUNTIFS( 'BA BackOffice'!$D:$D,"Incident", 'BA BackOffice'!$C:$C,"Apex", 'BA BackOffice'!$G:$G,1, 'BA BackOffice'!$I:$I,"Triaged", 'BA BackOffice'!$U:$U,"NO", 'BA BackOffice'!$N:$N,">="&$B$1, 'BA BackOffice'!$N:$N,"<"&$C$1+1 ) ) -> 0 | F6: =COUNTIFS( 'BA BackOffice'!$C:$C,"Apex", 'BA BackOffice'!$D:$D,"Incident", 'BA BackOffice'!$G:$G,1, 'BA BackOffice'!$U:$U,"<>YES", 'BA BackOffice'!$K:$K,"<"&$B$1, 'BA BackOffice'!$N:$N,"" ) + COUNTIFS( 'BA BackOffice'!$C:$C,"Apex", 'BA BackOffice'!$D:$D,"Incident", 'BA BackOffice'!$G:$G,1, 'BA BackOffice'!$U:$U,"<>YES", 'BA BackOffice'!$K:$K,"<"&$B$1, 'BA BackOffice'!$N:$N,">="&$B$1 ) + COUNTIFS( 'BA BackOffice'!$C:$C,"Apex", 'BA BackOffice'!$D:$D,"Incident", 'BA BackOffice'!$G:$G,1, 'BA BackOffice'!$U:$U,"<>YES", 'BA BackOffice'!$K:$K,">="&$B$1, 'BA BackOffice'!$K:$K,"<"&$C$1+1 ) - COUNTIFS( 'BA BackOffice'!$C:$C,"Apex", 'BA BackOffice'!$D:$D,"Incident", 'BA BackOffice'!$G:$G,1, 'BA BackOffice'!$U:$U,"<>YES", 'BA BackOffice'!$I:$I,"Closed", 'BA BackOffice'!$N:$N,">="&$B$1, 'BA BackOffice'!$N:$N,"<"&$C$1+1 ) - COUNTIFS( 'BA BackOffice'!$C:$C,"Apex", 'BA BackOffice'!$D:$D,"Incident", 'BA BackOffice'!$G:$G,1, 'BA BackOffice'!$U:$U,"<>YES", 'BA BackOffice'!$I:$I,"Triaged", 'BA BackOffice'!$N:$N,">="&$B$1, 'BA BackOffice'!$N:$N,"<"&$C$1+1 ) -> 0 | G6: =COUNTIFS( 'BA BackOffice'!$D:$D,"Incident", 'BA BackOffice'!$G:$G,2, 'BA BackOffice'!$C:$C,"Apex", 'BA BackOffice'!$U:$U,"NO", 'BA BackOffice'!$L:$L,">="&$B$1, 'BA BackOffice'!$L:$L,"<"&$C$1+1 ) -> 0 | H6: =SUM( COUNTIFS( 'BA BackOffice'!$D:$D,"Incident", 'BA BackOffice'!$C:$C,"Apex", 'BA BackOffice'!$G:$G,2, 'BA BackOffice'!$I:$I,"Closed", 'BA BackOffice'!$U:$U,"NO", 'BA BackOffice'!$N:$N,">="&$B$1, 'BA BackOffice'!$N:$N,"<"&$C$1+1 ), COUNTIFS( 'BA BackOffice'!$D:$D,"Incident", 'BA BackOffice'!$C:$C,"Apex", 'BA BackOffice'!$G:$G,2, 'BA BackOffice'!$I:$I,"Triaged", 'BA BackOffice'!$U:$U,"NO", 'BA BackOffice'!$N:$N,">="&$B$1, 'BA BackOffice'!$N:$N,"<"&$C$1+1 ) ) -> 0 | I6: =COUNTIFS( 'BA BackOffice'!$C:$C,"Apex", 'BA BackOffice'!$D:$D,"Incident", 'BA BackOffice'!$G:$G,2, 'BA BackOffice'!$U:$U,"<>YES", 'BA BackOffice'!$K:$K,"<"&$B$1, 'BA BackOffice'!$N:$N,"" ) + COUNTIFS( 'BA BackOffice'!$C:$C,"Apex", 'BA BackOffice'!$D:$D,"Incident", 'BA BackOffice'!$G:$G,2, 'BA BackOffice'!$U:$U,"<>YES", 'BA BackOffice'!$K:$K,"<"&$B$1, 'BA BackOffice'!$N:$N,">="&$B$1 ) + COUNTIFS( 'BA BackOffice'!$C:$C,"Apex", 'BA BackOffice'!$D:$D,"Incident", 'BA BackOffice'!$G:$G,2, 'BA BackOffice'!$U:$U,"<>YES", 'BA BackOffice'!$K:$K,">="&$B$1, 'BA BackOffice'!$K:$K,"<"&$C$1+1 ) - COUNTIFS( 'BA BackOffice'!$C:$C,"Apex", 'BA BackOffice'!$D:$D,"Incident", 'BA BackOffice'!$G:$G,2, 'BA BackOffice'!$U:$U,"<>YES", 'BA BackOffice'!$I:$I,"Closed", 'BA BackOffice'!$N:$N,">="&$B$1, 'BA BackOffice'!$N:$N,"<"&$C$1+1 ) - COUNTIFS( 'BA BackOffice'!$C:$C,"Apex", 'BA BackOffice'!$D:$D,"Incident", 'BA BackOffice'!$G:$G,2, 'BA BackOffice'!$U:$U,"<>YES", 'BA BackOffice'!$I:$I,"Triaged", 'BA BackOffice'!$N:$N,">="&$B$1, 'BA BackOffice'!$N:$N,"<"&$C$1+1 ) -> 0 | J6: =COUNTIFS( 'BA BackOffice'!$D:$D,"Incident", 'BA BackOffice'!$G:$G,3, 'BA BackOffice'!$C:$C,"Apex", 'BA BackOffice'!$U:$U,"NO", 'BA BackOffice'!$L:$L,">="&$B$1, 'BA BackOffice'!$L:$L,"<"&$C$1+1 ) -> 0 | K6: =SUM( COUNTIFS( 'BA BackOffice'!$D:$D,"Incident", 'BA BackOffice'!$C:$C,"Apex", 'BA BackOffice'!$G:$G,3, 'BA BackOffice'!$I:$I,"Closed", 'BA BackOffice'!$U:$U,"NO", 'BA BackOffice'!$N:$N,">="&$B$1, 'BA BackOffice'!$N:$N,"<"&$C$1+1 ), COUNTIFS( 'BA BackOffice'!$D:$D,"Incident", 'BA BackOffice'!$C:$C,"Apex", 'BA BackOffice'!$G:$G,3, 'BA BackOffice'!$I:$I,"Triaged", 'BA BackOffice'!$U:$U,"NO", 'BA BackOffice'!$N:$N,">="&$B$1, 'BA BackOffice'!$N:$N,"<"&$C$1+1 ) ) -> 0 | L6: =COUNTIFS( 'BA BackOffice'!$C:$C,"Apex", 'BA BackOffice'!$D:$D,"Incident", 'BA BackOffice'!$G:$G,3, 'BA BackOffice'!$U:$U,"<>YES", 'BA BackOffice'!$K:$K,"<"&$B$1, 'BA BackOffice'!$N:$N,"" ) + COUNTIFS( 'BA BackOffice'!$C:$C,"Apex", 'BA BackOffice'!$D:$D,"Incident", 'BA BackOffice'!$G:$G,3, 'BA BackOffice'!$U:$U,"<>YES", 'BA BackOffice'!$K:$K,"<"&$B$1, 'BA BackOffice'!$N:$N,">="&$B$1 ) + COUNTIFS( 'BA BackOffice'!$C:$C,"Apex", 'BA BackOffice'!$D:$D,"Incident", 'BA BackOffice'!$G:$G,3, 'BA BackOffice'!$U:$U,"<>YES", 'BA BackOffice'!$K:$K,">="&$B$1, 'BA BackOffice'!$K:$K,"<"&$C$1+1 ) - COUNTIFS( 'BA BackOffice'!$C:$C,"Apex", 'BA BackOffice'!$D:$D,"Incident", 'BA BackOffice'!$G:$G,3, 'BA BackOffice'!$U:$U,"<>YES", 'BA BackOffice'!$I:$I,"Closed", 'BA BackOffice'!$N:$N,">="&$B$1, 'BA BackOffice'!$N:$N,"<"&$C$1+1 ) - COUNTIFS( 'BA BackOffice'!$C:$C,"Apex", 'BA BackOffice'!$D:$D,"Incident", 'BA BackOffice'!$G:$G,3, 'BA BackOffice'!$U:$U,"<>YES", 'BA BackOffice'!$I:$I,"Triaged", 'BA BackOffice'!$N:$N,">="&$B$1, 'BA BackOffice'!$N:$N,"<"&$C$1+1 ) -> 0 | M6: =COUNTIFS( 'BA BackOffice'!$D:$D,"Incident", 'BA BackOffice'!$G:$G,4, 'BA BackOffice'!$C:$C,"Apex", 'BA BackOffice'!$U:$U,"NO", 'BA BackOffice'!$L:$L,">="&$B$1, 'BA BackOffice'!$L:$L,"<"&$C$1+1 ) -> 0 | N6: =SUM( COUNTIFS( 'BA BackOffice'!$D:$D,"Incident", 'BA BackOffice'!$C:$C,"Apex", 'BA BackOffice'!$G:$G,4, 'BA BackOffice'!$I:$I,"Closed", 'BA BackOffice'!$U:$U,"NO", 'BA BackOffice'!$N:$N,">="&$B$1, 'BA BackOffice'!$N:$N,"<"&$C$1+1 ), COUNTIFS( 'BA BackOffice'!$D:$D,"Incident", 'BA BackOffice'!$C:$C,"Apex", 'BA BackOffice'!$G:$G,4, 'BA BackOffice'!$I:$I,"Triaged", 'BA BackOffice'!$U:$U,"NO", 'BA BackOffice'!$N:$N,">="&$B$1, 'BA BackOffice'!$N:$N,"<"&$C$1+1 ) ) -> 0 | O6: =COUNTIFS( 'BA BackOffice'!$C:$C,"Apex", 'BA BackOffice'!$D:$D,"Incident", 'BA BackOffice'!$G:$G,4, 'BA BackOffice'!$U:$U,"<>YES", 'BA BackOffice'!$K:$K,"<"&$B$1, 'BA BackOffice'!$N:$N,"" ) + COUNTIFS( 'BA BackOffice'!$C:$C,"Apex", 'BA BackOffice'!$D:$D,"Incident", 'BA BackOffice'!$G:$G,4, 'BA BackOffice'!$U:$U,"<>YES", 'BA BackOffice'!$K:$K,"<"&$B$1, 'BA BackOffice'!$N:$N,">="&$B$1 ) + COUNTIFS( 'BA BackOffice'!$C:$C,"Apex", 'BA BackOffice'!$D:$D,"Incident", 'BA BackOffice'!$G:$G,4, 'BA BackOffice'!$U:$U,"<>YES", 'BA BackOffice'!$K:$K,">="&$B$1, 'BA BackOffice'!$K:$K,"<"&$C$1+1 ) - COUNTIFS( 'BA BackOffice'!$C:$C,"Apex", 'BA BackOffice'!$D:$D,"Incident", 'BA BackOffice'!$G:$G,4, 'BA BackOffice'!$U:$U,"<>YES", 'BA BackOffice'!$I:$I,"Closed", 'BA BackOffice'!$N:$N,">="&$B$1, 'BA BackOffice'!$N:$N,"<"&$C$1+1 ) - COUNTIFS( 'BA BackOffice'!$C:$C,"Apex", 'BA BackOffice'!$D:$D,"Incident", 'BA BackOffice'!$G:$G,4, 'BA BackOffice'!$U:$U,"<>YES", 'BA BackOffice'!$I:$I,"Triaged", 'BA BackOffice'!$N:$N,">="&$B$1, 'BA BackOffice'!$N:$N,"<"&$C$1+1 ) -> 0 | P6: =COUNTIFS( 'BA BackOffice'!$D:$D,"RFS", 'BA BackOffice'!$C:$C,"Apex", 'BA BackOffice'!$U:$U,"No", 'BA BackOffice'!$L:$L,">="&$B$1, 'BA BackOffice'!$L:$L,"<"&$C$1+1 ) -> 0 | Q6: =SUM( COUNTIFS( 'BA BackOffice'!$D:$D,"RFS", 'BA BackOffice'!$C:$C,"Apex", 'BA BackOffice'!$I:$I,"Closed", 'BA BackOffice'!$U:$U,"NO", 'BA BackOffice'!$N:$N,">="&$B$1, 'BA BackOffice'!$N:$N,"<"&$C$1+1 ), COUNTIFS( 'BA BackOffice'!$D:$D,"RFS", 'BA BackOffice'!$C:$C,"Apex", 'BA BackOffice'!$I:$I,"Triaged", 'BA BackOffice'!$U:$U,"NO", 'BA BackOffice'!$N:$N,">="&$B$1, 'BA BackOffice'!$N:$N,"<"&$C$1+1 ) ) -> 0 | R6: =COUNTIFS( 'BA BackOffice'!$D:$D,"RFS", 'BA BackOffice'!$C:$C,"Apex", 'BA BackOffice'!$U:$U,"<>YES", 'BA BackOffice'!$K:$K,"<"&$B$1, 'BA BackOffice'!$N:$N,"" ) + COUNTIFS( 'BA BackOffice'!$D:$D,"RFS", 'BA BackOffice'!$C:$C,"Apex", 'BA BackOffice'!$U:$U,"<>YES", 'BA BackOffice'!$K:$K,"<"&$B$1, 'BA BackOffice'!$N:$N,">="&$B$1 ) + COUNTIFS( 'BA BackOffice'!$D:$D,"RFS", 'BA BackOffice'!$C:$C,"Apex", 'BA BackOffice'!$U:$U,"<>YES", 'BA BackOffice'!$K:$K,">="&$B$1, 'BA BackOffice'!$K:$K,"<"&$C$1+1 ) - COUNTIFS( 'BA BackOffice'!$D:$D,"RFS", 'BA BackOffice'!$C:$C,"Apex", 'BA BackOffice'!$I:$I,"Closed", 'BA BackOffice'!$U:$U,"<>YES", 'BA BackOffice'!$N:$N,">="&$B$1, 'BA BackOffice'!$N:$N,"<"&$C$1+1 ) - COUNTIFS( 'BA BackOffice'!$D:$D,"RFS", 'BA BackOffice'!$C:$C,"Apex", 'BA BackOffice'!$I:$I,"Triaged", 'BA BackOffice'!$U:$U,"<>YES", 'BA BackOffice'!$N:$N,">="&$B$1, 'BA BackOffice'!$N:$N,"<"&$C$1+1 ) -> 4 | S6: =SUM( COUNTIFS( 'BA BackOffice'!$D:$D,"P_Ticket", 'BA BackOffice'!$G:$G,"Low", 'BA BackOffice'!$C:$C,"Apex", 'BA BackOffice'!$U:$U,"NO", 'BA BackOffice'!$L:$L,">="&$B$1, 'BA BackOffice'!$L:$L,"<"&$C$1+1 ), COUNTIFS( 'BA BackOffice'!$D:$D,"P_Ticket", 'BA BackOffice'!$G:$G,"Medium", 'BA BackOffice'!$C:$C,"Apex", 'BA BackOffice'!$U:$U,"NO", 'BA BackOffice'!$L:$L,">="&$B$1, 'BA BackOffice'!$L:$L,"<"&$C$1+1 ), COUNTIFS( 'BA BackOffice'!$D:$D,"P_Ticket", 'BA BackOffice'!$G:$G,"High", 'BA BackOffice'!$C:$C,"Apex", 'BA BackOffice'!$U:$U,"NO", 'BA BackOffice'!$L:$L,">="&$B$1, 'BA BackOffice'!$L:$L,"<"&$C$1+1 ) ) -> 0 | T6: =SUM(COUNTIFS('BA BackOffice'!$D:$D,"P_Ticket",'BA BackOffice'!$C:$C,"APEX",'BA BackOffice'!$G:$G,"Low",'BA BackOffice'!$I:$I,"Closed",'BA BackOffice'!$U:$U,"NO",'BA BackOffice'!$N:$N,"<"&$C$1+1,'BA BackOffice'!$N:$N,">="&$B$1),COUNTIFS('BA BackOffice'!$D:$D,"P_Ticket",'BA BackOffice'!$C:$C,"APEX",'BA BackOffice'!$G:$G,"Medium",'BA BackOffice'!$I:$I,"Closed",'BA BackOffice'!$U:$U,"NO",'BA BackOffice'!$N:$N,"<"&$C$1+1,'BA BackOffice'!$N:$N,">="&$B$1),COUNTIFS('BA BackOffice'!$D:$D,"P_Ticket",'BA BackOffice'!$C:$C,"APEX",'BA BackOffice'!$G:$G,"High",'BA BackOffice'!$I:$I,"Closed",'BA BackOffice'!$U:$U,"NO",'BA BackOffice'!$N:$N,"<"&$C$1+1,'BA BackOffice'!$N:$N,">="&$B$1),COUNTIFS('BA BackOffice'!$D:$D,"P_Ticket",'BA BackOffice'!$C:$C,"APEX",'BA BackOffice'!$G:$G,"Low",'BA BackOffice'!$I:$I,"Triaged",'BA BackOffice'!$U:$U,"NO",'BA BackOffice'!$N:$N,"<"&$C$1+1,'BA BackOffice'!$N:$N,">="&$B$1),COUNTIFS('BA BackOffice'!$D:$D,"P_Ticket",'BA BackOffice'!$C:$C,"APEX",'BA BackOffice'!$G:$G,"Medium",'BA BackOffice'!$I:$I,"Triaged",'BA BackOffice'!$U:$U,"NO",'BA BackOffice'!$N:$N,"<"&$C$1+1,'BA BackOffice'!$N:$N,">="&$B$1),COUNTIFS('BA BackOffice'!$D:$D,"P_Ticket",'BA BackOffice'!$C:$C,"APEX",'BA BackOffice'!$G:$G,"High",'BA BackOffice'!$I:$I,"Triaged",'BA BackOffice'!$U:$U,"NO",'BA BackOffice'!$N:$N,"<"&$C$1+1,'BA BackOffice'!$N:$N,">="&$B$1)) -> 0 | W6: =COUNTIFS( 'BA BackOffice'!$D:$D,"P_Ticket", 'BA BackOffice'!$G:$G,"High", 'BA BackOffice'!$C:$C,"Apex", 'BA BackOffice'!$U:$U,"NO", 'BA BackOffice'!$L:$L,">="&$B$1, 'BA BackOffice'!$L:$L,"<"&$C$1+1 ) -> 0 | X6: =SUM( COUNTIFS( 'BA BackOffice'!$D:$D,"P_Ticket", 'BA BackOffice'!$C:$C,"Apex", 'BA BackOffice'!$G:$G,"High", 'BA BackOffice'!$I:$I,"Closed", 'BA BackOffice'!$U:$U,"NO", 'BA BackOffice'!$N:$N,"<"&$C$1+1, 'BA BackOffice'!$N:$N,">="&$B$1 ), COUNTIFS( 'BA BackOffice'!$D:$D,"P_Ticket", 'BA BackOffice'!$C:$C,"Apex", 'BA BackOffice'!$G:$G,"High", 'BA BackOffice'!$I:$I,"Triaged", 'BA BackOffice'!$U:$U,"NO", 'BA BackOffice'!$N:$N,"<"&$C$1+1, 'BA BackOffice'!$N:$N,">="&$B$1 ) ) -> 0
A7: APPSUP_ETL APPSUP_TRILLIUM APPSUP_CRT APPSUP_BOA APPSUP_ICD50 | B7: BA | C7: TechTools | D7: =COUNTIFS( 'BA BackOffice'!$D:$D,"Incident", 'BA BackOffice'!$G:$G,1, 'BA BackOffice'!$C:$C,"TechTools", 'BA BackOffice'!$U:$U,"NO", 'BA BackOffice'!$L:$L,">="&$B$1, 'BA BackOffice'!$L:$L,"<"&$C$1+1 ) -> 0 | E7: =SUM( COUNTIFS( 'BA BackOffice'!$D:$D,"Incident", 'BA BackOffice'!$C:$C,"TechTools", 'BA BackOffice'!$G:$G,1, 'BA BackOffice'!$I:$I,"Closed", 'BA BackOffice'!$U:$U,"NO", 'BA BackOffice'!$N:$N,">="&$B$1, 'BA BackOffice'!$N:$N,"<"&$C$1+1 ), COUNTIFS( 'BA BackOffice'!$D:$D,"Incident", 'BA BackOffice'!$C:$C,"TechTools", 'BA BackOffice'!$G:$G,1, 'BA BackOffice'!$I:$I,"Triaged", 'BA BackOffice'!$U:$U,"NO", 'BA BackOffice'!$N:$N,">="&$B$1, 'BA BackOffice'!$N:$N,"<"&$C$1+1 ) ) -> 0 | F7: =COUNTIFS( 'BA BackOffice'!$C:$C,"TechTools", 'BA BackOffice'!$D:$D,"Incident", 'BA BackOffice'!$G:$G,1, 'BA BackOffice'!$U:$U,"<>YES", 'BA BackOffice'!$K:$K,"<"&$B$1, 'BA BackOffice'!$N:$N,"" ) + COUNTIFS( 'BA BackOffice'!$C:$C,"TechTools", 'BA BackOffice'!$D:$D,"Incident", 'BA BackOffice'!$G:$G,1, 'BA BackOffice'!$U:$U,"<>YES", 'BA BackOffice'!$K:$K,"<"&$B$1, 'BA BackOffice'!$N:$N,">="&$B$1 ) + COUNTIFS( 'BA BackOffice'!$C:$C,"TechTools", 'BA BackOffice'!$D:$D,"Incident", 'BA BackOffice'!$G:$G,1, 'BA BackOffice'!$U:$U,"<>YES", 'BA BackOffice'!$K:$K,">="&$B$1, 'BA BackOffice'!$K:$K,"<"&$C$1+1 ) - COUNTIFS( 'BA BackOffice'!$C:$C,"TechTools", 'BA BackOffice'!$D:$D,"Incident", 'BA BackOffice'!$G:$G,1, 'BA BackOffice'!$U:$U,"<>YES", 'BA BackOffice'!$I:$I,"Closed", 'BA BackOffice'!$N:$N,">="&$B$1, 'BA BackOffice'!$N:$N,"<"&$C$1+1 ) - COUNTIFS( 'BA BackOffice'!$C:$C,"TechTools", 'BA BackOffice'!$D:$D,"Incident", 'BA BackOffice'!$G:$G,1, 'BA BackOffice'!$U:$U,"<>YES", 'BA BackOffice'!$I:$I,"Triaged", 'BA BackOffice'!$N:$N,">="&$B$1, 'BA BackOffice'!$N:$N,"<"&$C$1+1 ) -> 0 | G7: =COUNTIFS( 'BA BackOffice'!$D:$D,"Incident", 'BA BackOffice'!$G:$G,2, 'BA BackOffice'!$C:$C,"TechTools", 'BA BackOffice'!$U:$U,"NO", 'BA BackOffice'!$L:$L,">="&$B$1, 'BA BackOffice'!$L:$L,"<"&$C$1+1 ) -> 0 | H7: =SUM( COUNTIFS( 'BA BackOffice'!$D:$D,"Incident", 'BA BackOffice'!$C:$C,"TechTools", 'BA BackOffice'!$G:$G,2, 'BA BackOffice'!$I:$I,"Closed", 'BA BackOffice'!$U:$U,"NO", 'BA BackOffice'!$N:$N,">="&$B$1, 'BA BackOffice'!$N:$N,"<"&$C$1+1 ), COUNTIFS( 'BA BackOffice'!$D:$D,"Incident", 'BA BackOffice'!$C:$C,"TechTools", 'BA BackOffice'!$G:$G,2, 'BA BackOffice'!$I:$I,"Triaged", 'BA BackOffice'!$U:$U,"NO", 'BA BackOffice'!$N:$N,">="&$B$1, 'BA BackOffice'!$N:$N,"<"&$C$1+1 ) ) -> 0 | I7: =COUNTIFS( 'BA BackOffice'!$C:$C,"TechTools", 'BA BackOffice'!$D:$D,"Incident", 'BA BackOffice'!$G:$G,2, 'BA BackOffice'!$U:$U,"<>YES", 'BA BackOffice'!$K:$K,"<"&$B$1, 'BA BackOffice'!$N:$N,"" ) + COUNTIFS( 'BA BackOffice'!$C:$C,"TechTools", 'BA BackOffice'!$D:$D,"Incident", 'BA BackOffice'!$G:$G,2, 'BA BackOffice'!$U:$U,"<>YES", 'BA BackOffice'!$K:$K,"<"&$B$1, 'BA BackOffice'!$N:$N,">="&$B$1 ) + COUNTIFS( 'BA BackOffice'!$C:$C,"TechTools", 'BA BackOffice'!$D:$D,"Incident", 'BA BackOffice'!$G:$G,2, 'BA BackOffice'!$U:$U,"<>YES", 'BA BackOffice'!$K:$K,">="&$B$1, 'BA BackOffice'!$K:$K,"<"&$C$1+1 ) - COUNTIFS( 'BA BackOffice'!$C:$C,"TechTools", 'BA BackOffice'!$D:$D,"Incident", 'BA BackOffice'!$G:$G,2, 'BA BackOffice'!$U:$U,"<>YES", 'BA BackOffice'!$I:$I,"Closed", 'BA BackOffice'!$N:$N,">="&$B$1, 'BA BackOffice'!$N:$N,"<"&$C$1+1 ) - COUNTIFS( 'BA BackOffice'!$C:$C,"TechTools", 'BA BackOffice'!$D:$D,"Incident", 'BA BackOffice'!$G:$G,2, 'BA BackOffice'!$U:$U,"<>YES", 'BA BackOffice'!$I:$I,"Triaged", 'BA BackOffice'!$N:$N,">="&$B$1, 'BA BackOffice'!$N:$N,"<"&$C$1+1 ) -> 0 | J7: =COUNTIFS( 'BA BackOffice'!$D:$D,"Incident", 'BA BackOffice'!$G:$G,3, 'BA BackOffice'!$C:$C,"TechTools", 'BA BackOffice'!$U:$U,"NO", 'BA BackOffice'!$L:$L,">="&$B$1, 'BA BackOffice'!$L:$L,"<"&$C$1+1 ) -> 6 | K7: =SUM( COUNTIFS( 'BA BackOffice'!$D:$D,"Incident", 'BA BackOffice'!$C:$C,"TechTools", 'BA BackOffice'!$G:$G,3, 'BA BackOffice'!$I:$I,"Closed", 'BA BackOffice'!$U:$U,"NO", 'BA BackOffice'!$N:$N,">="&$B$1, 'BA BackOffice'!$N:$N,"<"&$C$1+1 ), COUNTIFS( 'BA BackOffice'!$D:$D,"Incident", 'BA BackOffice'!$C:$C,"TechTools", 'BA BackOffice'!$G:$G,3, 'BA BackOffice'!$I:$I,"Triaged", 'BA BackOffice'!$U:$U,"NO", 'BA BackOffice'!$N:$N,">="&$B$1, 'BA BackOffice'!$N:$N,"<"&$C$1+1 ) ) -> 8 | L7: =COUNTIFS( 'BA BackOffice'!$C:$C,"TechTools", 'BA BackOffice'!$D:$D,"Incident", 'BA BackOffice'!$G:$G,3, 'BA BackOffice'!$U:$U,"<>YES", 'BA BackOffice'!$K:$K,"<"&$B$1, 'BA BackOffice'!$N:$N,"" ) + COUNTIFS( 'BA BackOffice'!$C:$C,"TechTools", 'BA BackOffice'!$D:$D,"Incident", 'BA BackOffice'!$G:$G,3, 'BA BackOffice'!$U:$U,"<>YES", 'BA BackOffice'!$K:$K,"<"&$B$1, 'BA BackOffice'!$N:$N,">="&$B$1 ) + COUNTIFS( 'BA BackOffice'!$C:$C,"TechTools", 'BA BackOffice'!$D:$D,"Incident", 'BA BackOffice'!$G:$G,3, 'BA BackOffice'!$U:$U,"<>YES", 'BA BackOffice'!$K:$K,">="&$B$1, 'BA BackOffice'!$K:$K,"<"&$C$1+1 ) - COUNTIFS( 'BA BackOffice'!$C:$C,"TechTools", 'BA BackOffice'!$D:$D,"Incident", 'BA BackOffice'!$G:$G,3, 'BA BackOffice'!$U:$U,"<>YES", 'BA BackOffice'!$I:$I,"Closed", 'BA BackOffice'!$N:$N,">="&$B$1, 'BA BackOffice'!$N:$N,"<"&$C$1+1 ) - COUNTIFS( 'BA BackOffice'!$C:$C,"TechTools", 'BA BackOffice'!$D:$D,"Incident", 'BA BackOffice'!$G:$G,3, 'BA BackOffice'!$U:$U,"<>YES", 'BA BackOffice'!$I:$I,"Triaged", 'BA BackOffice'!$N:$N,">="&$B$1, 'BA BackOffice'!$N:$N,"<"&$C$1+1 ) -> 0 | M7: =COUNTIFS( 'BA BackOffice'!$D:$D,"Incident", 'BA BackOffice'!$G:$G,4, 'BA BackOffice'!$C:$C,"TechTools", 'BA BackOffice'!$U:$U,"NO", 'BA BackOffice'!$L:$L,">="&$B$1, 'BA BackOffice'!$L:$L,"<"&$C$1+1 ) -> 7 | N7: =SUM( COUNTIFS( 'BA BackOffice'!$D:$D,"Incident", 'BA BackOffice'!$C:$C,"TechTools", 'BA BackOffice'!$G:$G,4, 'BA BackOffice'!$I:$I,"Closed", 'BA BackOffice'!$U:$U,"NO", 'BA BackOffice'!$N:$N,">="&$B$1, 'BA BackOffice'!$N:$N,"<"&$C$1+1 ), COUNTIFS( 'BA BackOffice'!$D:$D,"Incident", 'BA BackOffice'!$C:$C,"TechTools", 'BA BackOffice'!$G:$G,4, 'BA BackOffice'!$I:$I,"Triaged", 'BA BackOffice'!$U:$U,"NO", 'BA BackOffice'!$N:$N,">="&$B$1, 'BA BackOffice'!$N:$N,"<"&$C$1+1 ) ) -> 7 | O7: =COUNTIFS( 'BA BackOffice'!$C:$C,"TechTools", 'BA BackOffice'!$D:$D,"Incident", 'BA BackOffice'!$G:$G,4, 'BA BackOffice'!$U:$U,"<>YES", 'BA BackOffice'!$K:$K,"<"&$B$1, 'BA BackOffice'!$N:$N,"" ) + COUNTIFS( 'BA BackOffice'!$C:$C,"TechTools", 'BA BackOffice'!$D:$D,"Incident", 'BA BackOffice'!$G:$G,4, 'BA BackOffice'!$U:$U,"<>YES", 'BA BackOffice'!$K:$K,"<"&$B$1, 'BA BackOffice'!$N:$N,">="&$B$1 ) + COUNTIFS( 'BA BackOffice'!$C:$C,"TechTools", 'BA BackOffice'!$D:$D,"Incident", 'BA BackOffice'!$G:$G,4, 'BA BackOffice'!$U:$U,"<>YES", 'BA BackOffice'!$K:$K,">="&$B$1, 'BA BackOffice'!$K:$K,"<"&$C$1+1 ) - COUNTIFS( 'BA BackOffice'!$C:$C,"TechTools", 'BA BackOffice'!$D:$D,"Incident", 'BA BackOffice'!$G:$G,4, 'BA BackOffice'!$U:$U,"<>YES", 'BA BackOffice'!$I:$I,"Closed", 'BA BackOffice'!$N:$N,">="&$B$1, 'BA BackOffice'!$N:$N,"<"&$C$1+1 ) - COUNTIFS( 'BA BackOffice'!$C:$C,"TechTools", 'BA BackOffice'!$D:$D,"Incident", 'BA BackOffice'!$G:$G,4, 'BA BackOffice'!$U:$U,"<>YES", 'BA BackOffice'!$I:$I,"Triaged", 'BA BackOffice'!$N:$N,">="&$B$1, 'BA BackOffice'!$N:$N,"<"&$C$1+1 ) -> 0 | P7: =COUNTIFS( 'BA BackOffice'!$D:$D,"RFS", 'BA BackOffice'!$C:$C,"TechTools", 'BA BackOffice'!$U:$U,"No", 'BA BackOffice'!$L:$L,">="&$B$1, 'BA BackOffice'!$L:$L,"<"&$C$1+1 ) -> 0 | Q7: =SUM( COUNTIFS( 'BA BackOffice'!$D:$D,"RFS", 'BA BackOffice'!$C:$C,"TechTools", 'BA BackOffice'!$I:$I,"Closed", 'BA BackOffice'!$U:$U,"NO", 'BA BackOffice'!$N:$N,">="&$B$1, 'BA BackOffice'!$N:$N,"<"&$C$1+1 ), COUNTIFS( 'BA BackOffice'!$D:$D,"RFS", 'BA BackOffice'!$C:$C,"TechTools", 'BA BackOffice'!$I:$I,"Triaged", 'BA BackOffice'!$U:$U,"NO", 'BA BackOffice'!$N:$N,">="&$B$1, 'BA BackOffice'!$N:$N,"<"&$C$1+1 ) ) -> 3 | R7: =COUNTIFS( 'BA BackOffice'!$D:$D,"RFS", 'BA BackOffice'!$C:$C,"TechTools", 'BA BackOffice'!$U:$U,"<>YES", 'BA BackOffice'!$K:$K,"<"&$B$1, 'BA BackOffice'!$N:$N,"" ) + COUNTIFS( 'BA BackOffice'!$D:$D,"RFS", 'BA BackOffice'!$C:$C,"TechTools", 'BA BackOffice'!$U:$U,"<>YES", 'BA BackOffice'!$K:$K,"<"&$B$1, 'BA BackOffice'!$N:$N,">="&$B$1 ) + COUNTIFS( 'BA BackOffice'!$D:$D,"RFS", 'BA BackOffice'!$C:$C,"TechTools", 'BA BackOffice'!$U:$U,"<>YES", 'BA BackOffice'!$K:$K,">="&$B$1, 'BA BackOffice'!$K:$K,"<"&$C$1+1 ) - COUNTIFS( 'BA BackOffice'!$D:$D,"RFS", 'BA BackOffice'!$C:$C,"TechTools", 'BA BackOffice'!$I:$I,"Closed", 'BA BackOffice'!$U:$U,"<>YES", 'BA BackOffice'!$N:$N,">="&$B$1, 'BA BackOffice'!$N:$N,"<"&$C$1+1 ) - COUNTIFS( 'BA BackOffice'!$D:$D,"RFS", 'BA BackOffice'!$C:$C,"TechTools", 'BA BackOffice'!$I:$I,"Triaged", 'BA BackOffice'!$U:$U,"<>YES", 'BA BackOffice'!$N:$N,">="&$B$1, 'BA BackOffice'!$N:$N,"<"&$C$1+1 ) -> 1 | S7: =SUM( COUNTIFS( 'BA BackOffice'!$D:$D,"P_Ticket", 'BA BackOffice'!$G:$G,"Low", 'BA BackOffice'!$C:$C,"TechTools", 'BA BackOffice'!$U:$U,"NO", 'BA BackOffice'!$L:$L,">="&$B$1, 'BA BackOffice'!$L:$L,"<"&$C$1+1 ), COUNTIFS( 'BA BackOffice'!$D:$D,"P_Ticket", 'BA BackOffice'!$G:$G,"Medium", 'BA BackOffice'!$C:$C,"TechTools", 'BA BackOffice'!$U:$U,"NO", 'BA BackOffice'!$L:$L,">="&$B$1, 'BA BackOffice'!$L:$L,"<"&$C$1+1 ), COUNTIFS( 'BA BackOffice'!$D:$D,"P_Ticket", 'BA BackOffice'!$G:$G,"High", 'BA BackOffice'!$C:$C,"TechTools", 'BA BackOffice'!$U:$U,"NO", 'BA BackOffice'!$L:$L,">="&$B$1, 'BA BackOffice'!$L:$L,"<"&$C$1+1 ) ) -> 0 | T7: =SUM(COUNTIFS('BA BackOffice'!$D:$D,"P_Ticket",'BA BackOffice'!$C:$C,"TechTools",'BA BackOffice'!$G:$G,"Low",'BA BackOffice'!$I:$I,"Closed",'BA BackOffice'!$U:$U,"NO",'BA BackOffice'!$N:$N,"<"&$C$1+1,'BA BackOffice'!$N:$N,">="&$B$1),COUNTIFS('BA BackOffice'!$D:$D,"P_Ticket",'BA BackOffice'!$C:$C,"TechTools",'BA BackOffice'!$G:$G,"Medium",'BA BackOffice'!$I:$I,"Closed",'BA BackOffice'!$U:$U,"NO",'BA BackOffice'!$N:$N,"<"&$C$1+1,'BA BackOffice'!$N:$N,">="&$B$1),COUNTIFS('BA BackOffice'!$D:$D,"P_Ticket",'BA BackOffice'!$C:$C,"TechTools",'BA BackOffice'!$G:$G,"High",'BA BackOffice'!$I:$I,"Closed",'BA BackOffice'!$U:$U,"NO",'BA BackOffice'!$N:$N,"<"&$C$1+1,'BA BackOffice'!$N:$N,">="&$B$1),COUNTIFS('BA BackOffice'!$D:$D,"P_Ticket",'BA BackOffice'!$C:$C,"TechTools",'BA BackOffice'!$G:$G,"Low",'BA BackOffice'!$I:$I,"Triaged",'BA BackOffice'!$U:$U,"NO",'BA BackOffice'!$N:$N,"<"&$C$1+1,'BA BackOffice'!$N:$N,">="&$B$1),COUNTIFS('BA BackOffice'!$D:$D,"P_Ticket",'BA BackOffice'!$C:$C,"TechTools",'BA BackOffice'!$G:$G,"Medium",'BA BackOffice'!$I:$I,"Triaged",'BA BackOffice'!$U:$U,"NO",'BA BackOffice'!$N:$N,"<"&$C$1+1,'BA BackOffice'!$N:$N,">="&$B$1),COUNTIFS('BA BackOffice'!$D:$D,"P_Ticket",'BA BackOffice'!$C:$C,"TechTools",'BA BackOffice'!$G:$G,"High",'BA BackOffice'!$I:$I,"Triaged",'BA BackOffice'!$U:$U,"NO",'BA BackOffice'!$N:$N,"<"&$C$1+1,'BA BackOffice'!$N:$N,">="&$B$1)) -> 0 | W7: =COUNTIFS( 'BA BackOffice'!$D:$D,"P_Ticket", 'BA BackOffice'!$G:$G,"High", 'BA BackOffice'!$C:$C,"TechTools", 'BA BackOffice'!$U:$U,"NO", 'BA BackOffice'!$L:$L,">="&$B$1, 'BA BackOffice'!$L:$L,"<"&$C$1+1 ) -> 0 | X7: =SUM( COUNTIFS( 'BA BackOffice'!$D:$D,"P_Ticket", 'BA BackOffice'!$C:$C,"TechTools", 'BA BackOffice'!$G:$G,"High", 'BA BackOffice'!$I:$I,"Closed", 'BA BackOffice'!$U:$U,"NO", 'BA BackOffice'!$N:$N,"<"&$C$1+1, 'BA BackOffice'!$N:$N,">="&$B$1 ), COUNTIFS( 'BA BackOffice'!$D:$D,"P_Ticket", 'BA BackOffice'!$C:$C,"TechTools", 'BA BackOffice'!$G:$G,"High", 'BA BackOffice'!$I:$I,"Triaged", 'BA BackOffice'!$U:$U,"NO", 'BA BackOffice'!$N:$N,"<"&$C$1+1, 'BA BackOffice'!$N:$N,">="&$B$1 ) ) -> 0
A8: APPSUP_INFORM APPSUP_OPSDASHBOARD APPSUP_AIRPORTOPS APPSUP_AIMSLOUNGES APPSUP_OSCS APPSUP_BAGS APPSUP_RIBI APPSUP_PLUTO | B8: BA | C8: AO | D8: =COUNTIFS( 'BA AO'!$D:$D,"Incident", 'BA AO'!$G:$G,1, 'BA AO'!$U:$U,"NO", 'BA AO'!$L:$L,">="&$B$1, 'BA AO'!$L:$L,"<"&$C$1+1 ) -> 0 | E8: =SUM( COUNTIFS( 'BA AO'!$D:$D,"Incident", 'BA AO'!$G:$G,1, 'BA AO'!$I:$I,"Closed", 'BA AO'!$U:$U,"NO", 'BA AO'!$N:$N,">="&$B$1, 'BA AO'!$N:$N,"<"&$C$1+1 ), COUNTIFS( 'BA AO'!$D:$D,"Incident", 'BA AO'!$G:$G,1, 'BA AO'!$I:$I,"Triaged", 'BA AO'!$U:$U,"NO", 'BA AO'!$N:$N,">="&$B$1, 'BA AO'!$N:$N,"<"&$C$1+1 ) ) -> 0 | F8: =COUNTIFS( 'BA AO'!$D:$D,"Incident", 'BA AO'!$G:$G,1, 'BA AO'!$U:$U,"<>YES", 'BA AO'!$K:$K,"<"&$B$1, 'BA AO'!$N:$N,"" ) + COUNTIFS( 'BA AO'!$D:$D,"Incident", 'BA AO'!$G:$G,1, 'BA AO'!$U:$U,"<>YES", 'BA AO'!$K:$K,"<"&$B$1, 'BA AO'!$N:$N,">="&$B$1 ) + COUNTIFS( 'BA AO'!$D:$D,"Incident", 'BA AO'!$G:$G,1, 'BA AO'!$U:$U,"<>YES", 'BA AO'!$K:$K,">="&$B$1, 'BA AO'!$K:$K,"<"&$C$1+1 ) - COUNTIFS( 'BA AO'!$D:$D,"Incident", 'BA AO'!$G:$G,1, 'BA AO'!$U:$U,"<>YES", 'BA AO'!$I:$I,"Closed", 'BA AO'!$N:$N,">="&$B$1, 'BA AO'!$N:$N,"<"&$C$1+1 ) - COUNTIFS( 'BA AO'!$D:$D,"Incident", 'BA AO'!$G:$G,1, 'BA AO'!$U:$U,"<>YES", 'BA AO'!$I:$I,"Triaged", 'BA AO'!$N:$N,">="&$B$1, 'BA AO'!$N:$N,"<"&$C$1+1 ) -> 0 | G8: =COUNTIFS( 'BA AO'!$D:$D,"Incident", 'BA AO'!$G:$G,2, 'BA AO'!$U:$U,"NO", 'BA AO'!$L:$L,">="&$B$1, 'BA AO'!$L:$L,"<"&$C$1+1 ) -> 0 | H8: =SUM( COUNTIFS( 'BA AO'!$D:$D,"Incident", 'BA AO'!$G:$G,2, 'BA AO'!$I:$I,"Closed", 'BA AO'!$U:$U,"NO", 'BA AO'!$N:$N,">="&$B$1, 'BA AO'!$N:$N,"<"&$C$1+1 ), COUNTIFS( 'BA AO'!$D:$D,"Incident", 'BA AO'!$G:$G,2, 'BA AO'!$I:$I,"Triaged", 'BA AO'!$U:$U,"NO", 'BA AO'!$N:$N,">="&$B$1, 'BA AO'!$N:$N,"<"&$C$1+1 ) ) -> 0 | I8: =COUNTIFS( 'BA AO'!$D:$D,"Incident", 'BA AO'!$G:$G,2, 'BA AO'!$U:$U,"<>YES", 'BA AO'!$K:$K,"<"&$B$1, 'BA AO'!$N:$N,"" ) + COUNTIFS( 'BA AO'!$D:$D,"Incident", 'BA AO'!$G:$G,2, 'BA AO'!$U:$U,"<>YES", 'BA AO'!$K:$K,"<"&$B$1, 'BA AO'!$N:$N,">="&$B$1 ) + COUNTIFS( 'BA AO'!$D:$D,"Incident", 'BA AO'!$G:$G,2, 'BA AO'!$U:$U,"<>YES", 'BA AO'!$K:$K,">="&$B$1, 'BA AO'!$K:$K,"<"&$C$1+1 ) - COUNTIFS( 'BA AO'!$D:$D,"Incident", 'BA AO'!$G:$G,2, 'BA AO'!$U:$U,"<>YES", 'BA AO'!$I:$I,"Closed", 'BA AO'!$N:$N,">="&$B$1, 'BA AO'!$N:$N,"<"&$C$1+1 ) - COUNTIFS( 'BA AO'!$D:$D,"Incident", 'BA AO'!$G:$G,2, 'BA AO'!$U:$U,"<>YES", 'BA AO'!$I:$I,"Triaged", 'BA AO'!$N:$N,">="&$B$1, 'BA AO'!$N:$N,"<"&$C$1+1 ) -> 0 | J8: =COUNTIFS( 'BA AO'!$D:$D,"Incident", 'BA AO'!$G:$G,3, 'BA AO'!$U:$U,"NO", 'BA AO'!$L:$L,">="&$B$1, 'BA AO'!$L:$L,"<"&$C$1+1 ) -> 0 | K8: =SUM( COUNTIFS( 'BA AO'!$D:$D,"Incident", 'BA AO'!$G:$G,3, 'BA AO'!$I:$I,"Closed", 'BA AO'!$U:$U,"NO", 'BA AO'!$N:$N,">="&$B$1, 'BA AO'!$N:$N,"<"&$C$1+1 ), COUNTIFS( 'BA AO'!$D:$D,"Incident", 'BA AO'!$G:$G,3, 'BA AO'!$I:$I,"Triaged", 'BA AO'!$U:$U,"NO", 'BA AO'!$N:$N,">="&$B$1, 'BA AO'!$N:$N,"<"&$C$1+1 ) ) -> 2 | L8: =COUNTIFS( 'BA AO'!$D:$D,"Incident", 'BA AO'!$G:$G,3, 'BA AO'!$U:$U,"<>YES", 'BA AO'!$K:$K,"<"&$B$1, 'BA AO'!$N:$N,"" ) + COUNTIFS( 'BA AO'!$D:$D,"Incident", 'BA AO'!$G:$G,3, 'BA AO'!$U:$U,"<>YES", 'BA AO'!$K:$K,"<"&$B$1, 'BA AO'!$N:$N,">="&$B$1 ) + COUNTIFS( 'BA AO'!$D:$D,"Incident", 'BA AO'!$G:$G,3, 'BA AO'!$U:$U,"<>YES", 'BA AO'!$K:$K,">="&$B$1, 'BA AO'!$K:$K,"<"&$C$1+1 ) - COUNTIFS( 'BA AO'!$D:$D,"Incident", 'BA AO'!$G:$G,3, 'BA AO'!$U:$U,"<>YES", 'BA AO'!$I:$I,"Closed", 'BA AO'!$N:$N,">="&$B$1, 'BA AO'!$N:$N,"<"&$C$1+1 ) - COUNTIFS( 'BA AO'!$D:$D,"Incident", 'BA AO'!$G:$G,3, 'BA AO'!$U:$U,"<>YES", 'BA AO'!$I:$I,"Triaged", 'BA AO'!$N:$N,">="&$B$1, 'BA AO'!$N:$N,"<"&$C$1+1 ) -> 55 | M8: =COUNTIFS( 'BA AO'!$D:$D,"Incident", 'BA AO'!$G:$G,4, 'BA AO'!$U:$U,"NO", 'BA AO'!$L:$L,">="&$B$1, 'BA AO'!$L:$L,"<"&$C$1+1 ) -> 4 | N8: =SUM( COUNTIFS( 'BA AO'!$D:$D,"Incident", 'BA AO'!$G:$G,4, 'BA AO'!$I:$I,"Closed", 'BA AO'!$U:$U,"NO", 'BA AO'!$N:$N,">="&$B$1, 'BA AO'!$N:$N,"<"&$C$1+1 ), COUNTIFS( 'BA AO'!$D:$D,"Incident", 'BA AO'!$G:$G,4, 'BA AO'!$I:$I,"Triaged", 'BA AO'!$U:$U,"NO", 'BA AO'!$N:$N,">="&$B$1, 'BA AO'!$N:$N,"<"&$C$1+1 ) ) -> 3 | O8: =COUNTIFS( 'BA AO'!$D:$D,"Incident", 'BA AO'!$G:$G,4, 'BA AO'!$U:$U,"<>YES", 'BA AO'!$K:$K,"<"&$B$1, 'BA AO'!$N:$N,"" ) + COUNTIFS( 'BA AO'!$D:$D,"Incident", 'BA AO'!$G:$G,4, 'BA AO'!$U:$U,"<>YES", 'BA AO'!$K:$K,"<"&$B$1, 'BA AO'!$N:$N,">="&$B$1 ) + COUNTIFS( 'BA AO'!$D:$D,"Incident", 'BA AO'!$G:$G,4, 'BA AO'!$U:$U,"<>YES", 'BA AO'!$K:$K,">="&$B$1, 'BA AO'!$K:$K,"<"&$C$1+1 ) - COUNTIFS( 'BA AO'!$D:$D,"Incident", 'BA AO'!$G:$G,4, 'BA AO'!$U:$U,"<>YES", 'BA AO'!$I:$I,"Closed", 'BA AO'!$N:$N,">="&$B$1, 'BA AO'!$N:$N,"<"&$C$1+1 ) - COUNTIFS( 'BA AO'!$D:$D,"Incident", 'BA AO'!$G:$G,4, 'BA AO'!$U:$U,"<>YES", 'BA AO'!$I:$I,"Triaged", 'BA AO'!$N:$N,">="&$B$1, 'BA AO'!$N:$N,"<"&$C$1+1 ) -> 56 | P8: =COUNTIFS( 'BA AO'!$D:$D,"RFS", 'BA AO'!$U:$U,"NO", 'BA AO'!$L:$L,">="&$B$1, 'BA AO'!$L:$L,"<"&$C$1+1 ) -> 0 | Q8: =SUM( COUNTIFS( 'BA AO'!$D:$D,"RFS", 'BA AO'!$I:$I,"Closed", 'BA AO'!$U:$U,"NO", 'BA AO'!$N:$N,">="&$B$1, 'BA AO'!$N:$N,"<"&$C$1+1 ), COUNTIFS( 'BA AO'!$D:$D,"RFS", 'BA AO'!$I:$I,"Triaged", 'BA AO'!$U:$U,"NO", 'BA AO'!$N:$N,">="&$B$1, 'BA AO'!$N:$N,"<"&$C$1+1 ) ) -> 1 | R8: =COUNTIFS( 'BA AO'!$D:$D,"RFS", 'BA AO'!$U:$U,"<>YES", 'BA AO'!$K:$K,"<"&$B$1, 'BA AO'!$N:$N,"" ) + COUNTIFS( 'BA AO'!$D:$D,"RFS", 'BA AO'!$U:$U,"<>YES", 'BA AO'!$K:$K,"<"&$B$1, 'BA AO'!$N:$N,">="&$B$1 ) + COUNTIFS( 'BA AO'!$D:$D,"RFS", 'BA AO'!$U:$U,"<>YES", 'BA AO'!$K:$K,">="&$B$1, 'BA AO'!$K:$K,"<"&$C$1+1 ) - COUNTIFS( 'BA AO'!$D:$D,"RFS", 'BA AO'!$I:$I,"Closed", 'BA AO'!$U:$U,"<>YES", 'BA AO'!$N:$N,">="&$B$1, 'BA AO'!$N:$N,"<"&$C$1+1 ) - COUNTIFS( 'BA AO'!$D:$D,"RFS", 'BA AO'!$I:$I,"Triaged", 'BA AO'!$U:$U,"<>YES", 'BA AO'!$N:$N,">="&$B$1, 'BA AO'!$N:$N,"<"&$C$1+1 ) -> 79 | S8: =SUM( COUNTIFS( 'BA AO'!$D:$D,"P_Ticket", 'BA AO'!$G:$G,"Low", 'BA AO'!$U:$U,"NO", 'BA AO'!$L:$L,">="&$B$1, 'BA AO'!$L:$L,"<"&$C$1+1 ), COUNTIFS( 'BA AO'!$D:$D,"P_Ticket", 'BA AO'!$G:$G,"Medium", 'BA AO'!$U:$U,"NO", 'BA AO'!$L:$L,">="&$B$1, 'BA AO'!$L:$L,"<"&$C$1+1 ), COUNTIFS( 'BA AO'!$D:$D,"P_Ticket", 'BA AO'!$G:$G,"High", 'BA AO'!$U:$U,"NO", 'BA AO'!$L:$L,">="&$B$1, 'BA AO'!$L:$L,"<"&$C$1+1 ) ) -> 0 | T8: =SUM(COUNTIFS('BA AO'!$D:$D,"P_Ticket",'BA AO'!$G:$G,"Low",'BA AO'!$I:$I,"Closed",'BA AO'!$U:$U,"NO",'BA AO'!$N:$N,"<"&$C$1+1,'BA AO'!$N:$N,">="&$B$1),COUNTIFS('BA AO'!$D:$D,"P_Ticket",'BA AO'!$G:$G,"Medium",'BA AO'!$I:$I,"Closed",'BA AO'!$U:$U,"NO",'BA AO'!$N:$N,"<"&$C$1+1,'BA AO'!$N:$N,">="&$B$1),COUNTIFS('BA AO'!$D:$D,"P_Ticket",'BA AO'!$G:$G,"High",'BA AO'!$I:$I,"Closed",'BA AO'!$U:$U,"NO",'BA AO'!$N:$N,"<"&$C$1+1,'BA AO'!$N:$N,">="&$B$1),COUNTIFS('BA AO'!$D:$D,"P_Ticket",'BA AO'!$G:$G,"Low",'BA AO'!$I:$I,"Triaged",'BA AO'!$U:$U,"NO",'BA AO'!$N:$N,"<"&$C$1+1,'BA AO'!$N:$N,">="&$B$1),COUNTIFS('BA AO'!$D:$D,"P_Ticket",'BA AO'!$G:$G,"Medium",'BA AO'!$I:$I,"Triaged",'BA AO'!$U:$U,"NO",'BA AO'!$N:$N,"<"&$C$1+1,'BA AO'!$N:$N,">="&$B$1),COUNTIFS('BA AO'!$D:$D,"P_Ticket",'BA AO'!$G:$G,"High",'BA AO'!$I:$I,"Triaged",'BA AO'!$U:$U,"NO",'BA AO'!$N:$N,"<"&$C$1+1,'BA AO'!$N:$N,">="&$B$1)) -> 0 | W8: =COUNTIFS( 'BA AO'!$D:$D,"P_Ticket", 'BA AO'!$G:$G,"High", 'BA AO'!$U:$U,"NO", 'BA AO'!$L:$L,">="&$B$1, 'BA AO'!$L:$L,"<"&$C$1+1 ) -> 0 | X8: =SUM( COUNTIFS( 'BA AO'!$D:$D,"P_Ticket", 'BA AO'!$G:$G,"High", 'BA AO'!$I:$I,"Closed", 'BA AO'!$U:$U,"NO", 'BA AO'!$N:$N,"<"&$C$1+1, 'BA AO'!$N:$N,">="&$B$1 ), COUNTIFS( 'BA AO'!$D:$D,"P_Ticket", 'BA AO'!$G:$G,"High", 'BA AO'!$I:$I,"Triaged", 'BA AO'!$U:$U,"NO", 'BA AO'!$N:$N,"<"&$C$1+1, 'BA AO'!$N:$N,">="&$B$1 ) ) -> 0
A9: APPSUP_BAENTMOBAPPS | B9: BA | C9: Mobile | D9: =COUNTIFS( 'BA Mobile'!$D:$D,"Incident", 'BA Mobile'!$G:$G,1, 'BA Mobile'!$U:$U,"NO", 'BA Mobile'!$L:$L,">="&$B$1, 'BA Mobile'!$L:$L,"<"&$C$1+1 ) -> 0 | E9: =SUM( COUNTIFS( 'BA Mobile'!$D:$D,"Incident", 'BA Mobile'!$G:$G,1, 'BA Mobile'!$I:$I,"Closed", 'BA Mobile'!$U:$U,"NO", 'BA Mobile'!$N:$N,">="&$B$1, 'BA Mobile'!$N:$N,"<"&$C$1+1 ), COUNTIFS( 'BA Mobile'!$D:$D,"Incident", 'BA Mobile'!$G:$G,1, 'BA Mobile'!$I:$I,"Triaged", 'BA Mobile'!$U:$U,"NO", 'BA Mobile'!$N:$N,">="&$B$1, 'BA Mobile'!$N:$N,"<"&$C$1+1 ) ) -> 0 | F9: =COUNTIFS( 'BA Mobile'!$D:$D,"Incident", 'BA Mobile'!$G:$G,1, 'BA Mobile'!$U:$U,"<>YES", 'BA Mobile'!$K:$K,"<"&$B$1, 'BA Mobile'!$N:$N,"" ) + COUNTIFS( 'BA Mobile'!$D:$D,"Incident", 'BA Mobile'!$G:$G,1, 'BA Mobile'!$U:$U,"<>YES", 'BA Mobile'!$K:$K,"<"&$B$1, 'BA Mobile'!$N:$N,">="&$B$1 ) + COUNTIFS( 'BA Mobile'!$D:$D,"Incident", 'BA Mobile'!$G:$G,1, 'BA Mobile'!$U:$U,"<>YES", 'BA Mobile'!$K:$K,">="&$B$1, 'BA Mobile'!$K:$K,"<"&$C$1+1 ) - COUNTIFS( 'BA Mobile'!$D:$D,"Incident", 'BA Mobile'!$G:$G,1, 'BA Mobile'!$U:$U,"<>YES", 'BA Mobile'!$I:$I,"Closed", 'BA Mobile'!$N:$N,">="&$B$1, 'BA Mobile'!$N:$N,"<"&$C$1+1 ) - COUNTIFS( 'BA Mobile'!$D:$D,"Incident", 'BA Mobile'!$G:$G,1, 'BA Mobile'!$U:$U,"<>YES", 'BA Mobile'!$I:$I,"Triaged", 'BA Mobile'!$N:$N,">="&$B$1, 'BA Mobile'!$N:$N,"<"&$C$1+1 ) -> 0 | G9: =COUNTIFS( 'BA Mobile'!$D:$D,"Incident", 'BA Mobile'!$G:$G,2, 'BA Mobile'!$U:$U,"NO", 'BA Mobile'!$L:$L,">="&$B$1, 'BA Mobile'!$L:$L,"<"&$C$1+1 ) -> 0 | H9: =SUM( COUNTIFS( 'BA Mobile'!$D:$D,"Incident", 'BA Mobile'!$G:$G,2, 'BA Mobile'!$I:$I,"Closed", 'BA Mobile'!$U:$U,"NO", 'BA Mobile'!$N:$N,">="&$B$1, 'BA Mobile'!$N:$N,"<"&$C$1+1 ), COUNTIFS( 'BA Mobile'!$D:$D,"Incident", 'BA Mobile'!$G:$G,2, 'BA Mobile'!$I:$I,"Triaged", 'BA Mobile'!$U:$U,"NO", 'BA Mobile'!$N:$N,">="&$B$1, 'BA Mobile'!$N:$N,"<"&$C$1+1 ) ) -> 0 | I9: =COUNTIFS( 'BA Mobile'!$D:$D,"Incident", 'BA Mobile'!$G:$G,2, 'BA Mobile'!$U:$U,"<>YES", 'BA Mobile'!$K:$K,"<"&$B$1, 'BA Mobile'!$N:$N,"" ) + COUNTIFS( 'BA Mobile'!$D:$D,"Incident", 'BA Mobile'!$G:$G,2, 'BA Mobile'!$U:$U,"<>YES", 'BA Mobile'!$K:$K,"<"&$B$1, 'BA Mobile'!$N:$N,">="&$B$1 ) + COUNTIFS( 'BA Mobile'!$D:$D,"Incident", 'BA Mobile'!$G:$G,2, 'BA Mobile'!$U:$U,"<>YES", 'BA Mobile'!$K:$K,">="&$B$1, 'BA Mobile'!$K:$K,"<"&$C$1+1 ) - COUNTIFS( 'BA Mobile'!$D:$D,"Incident", 'BA Mobile'!$G:$G,2, 'BA Mobile'!$U:$U,"<>YES", 'BA Mobile'!$I:$I,"Closed", 'BA Mobile'!$N:$N,">="&$B$1, 'BA Mobile'!$N:$N,"<"&$C$1+1 ) - COUNTIFS( 'BA Mobile'!$D:$D,"Incident", 'BA Mobile'!$G:$G,2, 'BA Mobile'!$U:$U,"<>YES", 'BA Mobile'!$I:$I,"Triaged", 'BA Mobile'!$N:$N,">="&$B$1, 'BA Mobile'!$N:$N,"<"&$C$1+1 ) -> 0 | J9: =COUNTIFS( 'BA Mobile'!$D:$D,"Incident", 'BA Mobile'!$G:$G,3, 'BA Mobile'!$U:$U,"NO", 'BA Mobile'!$L:$L,">="&$B$1, 'BA Mobile'!$L:$L,"<"&$C$1+1 ) -> 0 | K9: =SUM( COUNTIFS( 'BA Mobile'!$D:$D,"Incident", 'BA Mobile'!$G:$G,3, 'BA Mobile'!$I:$I,"Closed", 'BA Mobile'!$U:$U,"NO", 'BA Mobile'!$N:$N,">="&$B$1, 'BA Mobile'!$N:$N,"<"&$C$1+1 ), COUNTIFS( 'BA Mobile'!$D:$D,"Incident", 'BA Mobile'!$G:$G,3, 'BA Mobile'!$I:$I,"Triaged", 'BA Mobile'!$U:$U,"NO", 'BA Mobile'!$N:$N,">="&$B$1, 'BA Mobile'!$N:$N,"<"&$C$1+1 ) ) -> 0 | L9: =COUNTIFS( 'BA Mobile'!$D:$D,"Incident", 'BA Mobile'!$G:$G,3, 'BA Mobile'!$U:$U,"<>YES", 'BA Mobile'!$K:$K,"<"&$B$1, 'BA Mobile'!$N:$N,"" ) + COUNTIFS( 'BA Mobile'!$D:$D,"Incident", 'BA Mobile'!$G:$G,3, 'BA Mobile'!$U:$U,"<>YES", 'BA Mobile'!$K:$K,"<"&$B$1, 'BA Mobile'!$N:$N,">="&$B$1 ) + COUNTIFS( 'BA Mobile'!$D:$D,"Incident", 'BA Mobile'!$G:$G,3, 'BA Mobile'!$U:$U,"<>YES", 'BA Mobile'!$K:$K,">="&$B$1, 'BA Mobile'!$K:$K,"<"&$C$1+1 ) - COUNTIFS( 'BA Mobile'!$D:$D,"Incident", 'BA Mobile'!$G:$G,3, 'BA Mobile'!$U:$U,"<>YES", 'BA Mobile'!$I:$I,"Closed", 'BA Mobile'!$N:$N,">="&$B$1, 'BA Mobile'!$N:$N,"<"&$C$1+1 ) - COUNTIFS( 'BA Mobile'!$D:$D,"Incident", 'BA Mobile'!$G:$G,3, 'BA Mobile'!$U:$U,"<>YES", 'BA Mobile'!$I:$I,"Triaged", 'BA Mobile'!$N:$N,">="&$B$1, 'BA Mobile'!$N:$N,"<"&$C$1+1 ) -> 5 | M9: =COUNTIFS( 'BA Mobile'!$D:$D,"Incident", 'BA Mobile'!$G:$G,4, 'BA Mobile'!$U:$U,"NO", 'BA Mobile'!$L:$L,">="&$B$1, 'BA Mobile'!$L:$L,"<"&$C$1+1 ) -> 0 | N9: =SUM( COUNTIFS( 'BA Mobile'!$D:$D,"Incident", 'BA Mobile'!$G:$G,4, 'BA Mobile'!$I:$I,"Closed", 'BA Mobile'!$U:$U,"NO", 'BA Mobile'!$N:$N,">="&$B$1, 'BA Mobile'!$N:$N,"<"&$C$1+1 ), COUNTIFS( 'BA Mobile'!$D:$D,"Incident", 'BA Mobile'!$G:$G,4, 'BA Mobile'!$I:$I,"Triaged", 'BA Mobile'!$U:$U,"NO", 'BA Mobile'!$N:$N,">="&$B$1, 'BA Mobile'!$N:$N,"<"&$C$1+1 ) ) -> 1 | O9: =COUNTIFS( 'BA Mobile'!$D:$D,"Incident", 'BA Mobile'!$G:$G,4, 'BA Mobile'!$U:$U,"<>YES", 'BA Mobile'!$K:$K,"<"&$B$1, 'BA Mobile'!$N:$N,"" ) + COUNTIFS( 'BA Mobile'!$D:$D,"Incident", 'BA Mobile'!$G:$G,4, 'BA Mobile'!$U:$U,"<>YES", 'BA Mobile'!$K:$K,"<"&$B$1, 'BA Mobile'!$N:$N,">="&$B$1 ) + COUNTIFS( 'BA Mobile'!$D:$D,"Incident", 'BA Mobile'!$G:$G,4, 'BA Mobile'!$U:$U,"<>YES", 'BA Mobile'!$K:$K,">="&$B$1, 'BA Mobile'!$K:$K,"<"&$C$1+1 ) - COUNTIFS( 'BA Mobile'!$D:$D,"Incident", 'BA Mobile'!$G:$G,4, 'BA Mobile'!$U:$U,"<>YES", 'BA Mobile'!$I:$I,"Closed", 'BA Mobile'!$N:$N,">="&$B$1, 'BA Mobile'!$N:$N,"<"&$C$1+1 ) - COUNTIFS( 'BA Mobile'!$D:$D,"Incident", 'BA Mobile'!$G:$G,4, 'BA Mobile'!$U:$U,"<>YES", 'BA Mobile'!$I:$I,"Triaged", 'BA Mobile'!$N:$N,">="&$B$1, 'BA Mobile'!$N:$N,"<"&$C$1+1 ) -> 55 | P9: =COUNTIFS( 'BA Mobile'!$D:$D,"RFS", 'BA Mobile'!$U:$U,"NO", 'BA Mobile'!$L:$L,">="&$B$1, 'BA Mobile'!$L:$L,"<"&$C$1+1 ) -> 0 | Q9: =SUM( COUNTIFS( 'BA Mobile'!$D:$D,"RFS", 'BA Mobile'!$I:$I,"Closed", 'BA Mobile'!$U:$U,"NO", 'BA Mobile'!$N:$N,">="&$B$1, 'BA Mobile'!$N:$N,"<"&$C$1+1 ), COUNTIFS( 'BA Mobile'!$D:$D,"RFS", 'BA Mobile'!$I:$I,"Triaged", 'BA Mobile'!$U:$U,"NO", 'BA Mobile'!$N:$N,">="&$B$1, 'BA Mobile'!$N:$N,"<"&$C$1+1 ) ) -> 0 | R9: =COUNTIFS( 'BA Mobile'!$D:$D,"RFS", 'BA Mobile'!$U:$U,"<>YES", 'BA Mobile'!$K:$K,"<"&$B$1, 'BA Mobile'!$N:$N,"" ) + COUNTIFS( 'BA Mobile'!$D:$D,"RFS", 'BA Mobile'!$U:$U,"<>YES", 'BA Mobile'!$K:$K,"<"&$B$1, 'BA Mobile'!$N:$N,">="&$B$1 ) + COUNTIFS( 'BA Mobile'!$D:$D,"RFS", 'BA Mobile'!$U:$U,"<>YES", 'BA Mobile'!$K:$K,">="&$B$1, 'BA Mobile'!$K:$K,"<"&$C$1+1 ) - COUNTIFS( 'BA Mobile'!$D:$D,"RFS", 'BA Mobile'!$I:$I,"Closed", 'BA Mobile'!$U:$U,"<>YES", 'BA Mobile'!$N:$N,">="&$B$1, 'BA Mobile'!$N:$N,"<"&$C$1+1 ) - COUNTIFS( 'BA Mobile'!$D:$D,"RFS", 'BA Mobile'!$I:$I,"Triaged", 'BA Mobile'!$U:$U,"<>YES", 'BA Mobile'!$N:$N,">="&$B$1, 'BA Mobile'!$N:$N,"<"&$C$1+1 ) -> 7 | S9: =SUM( COUNTIFS( 'BA Mobile'!$D:$D,"P_Ticket", 'BA Mobile'!$G:$G,"Low", 'BA Mobile'!$U:$U,"NO", 'BA Mobile'!$L:$L,">="&$B$1, 'BA Mobile'!$L:$L,"<"&$C$1+1 ), COUNTIFS( 'BA Mobile'!$D:$D,"P_Ticket", 'BA Mobile'!$G:$G,"Medium", 'BA Mobile'!$U:$U,"NO", 'BA Mobile'!$L:$L,">="&$B$1, 'BA Mobile'!$L:$L,"<"&$C$1+1 ), COUNTIFS( 'BA Mobile'!$D:$D,"P_Ticket", 'BA Mobile'!$G:$G,"High", 'BA Mobile'!$U:$U,"NO", 'BA Mobile'!$L:$L,">="&$B$1, 'BA Mobile'!$L:$L,"<"&$C$1+1 ) ) -> 0 | T9: =SUM(COUNTIFS('BA Mobile'!$D:$D,"P_Ticket",'BA Mobile'!$G:$G,"Low",'BA Mobile'!$I:$I,"Closed",'BA Mobile'!$U:$U,"NO",'BA Mobile'!$N:$N,"<"&$C$1+1,'BA Mobile'!$N:$N,">="&$B$1),COUNTIFS('BA Mobile'!$D:$D,"P_Ticket",'BA Mobile'!$G:$G,"Medium",'BA Mobile'!$I:$I,"Closed",'BA Mobile'!$U:$U,"NO",'BA Mobile'!$N:$N,"<"&$C$1+1,'BA Mobile'!$N:$N,">="&$B$1),COUNTIFS('BA Mobile'!$D:$D,"P_Ticket",'BA Mobile'!$G:$G,"High",'BA Mobile'!$I:$I,"Closed",'BA Mobile'!$U:$U,"NO",'BA Mobile'!$N:$N,"<"&$C$1+1,'BA Mobile'!$N:$N,">="&$B$1),COUNTIFS('BA Mobile'!$D:$D,"P_Ticket",'BA Mobile'!$G:$G,"Low",'BA Mobile'!$I:$I,"Triaged",'BA Mobile'!$U:$U,"NO",'BA Mobile'!$N:$N,"<"&$C$1+1,'BA Mobile'!$N:$N,">="&$B$1),COUNTIFS('BA Mobile'!$D:$D,"P_Ticket",'BA Mobile'!$G:$G,"Medium",'BA Mobile'!$I:$I,"Triaged",'BA Mobile'!$U:$U,"NO",'BA Mobile'!$N:$N,"<"&$C$1+1,'BA Mobile'!$N:$N,">="&$B$1),COUNTIFS('BA Mobile'!$D:$D,"P_Ticket",'BA Mobile'!$G:$G,"High",'BA Mobile'!$I:$I,"Triaged",'BA Mobile'!$U:$U,"NO",'BA Mobile'!$N:$N,"<"&$C$1+1,'BA Mobile'!$N:$N,">="&$B$1)) -> 0 | W9: =COUNTIFS( 'BA Mobile'!$D:$D,"P_Ticket", 'BA Mobile'!$G:$G,"High", 'BA Mobile'!$U:$U,"NO", 'BA Mobile'!$L:$L,">="&$B$1, 'BA Mobile'!$L:$L,"<"&$C$1+1 ) -> 0 | X9: =SUM( COUNTIFS( 'BA Mobile'!$D:$D,"P_Ticket", 'BA Mobile'!$G:$G,"High", 'BA Mobile'!$I:$I,"Closed", 'BA Mobile'!$U:$U,"NO", 'BA Mobile'!$N:$N,"<"&$C$1+1, 'BA Mobile'!$N:$N,">="&$B$1 ), COUNTIFS( 'BA Mobile'!$D:$D,"P_Ticket", 'BA Mobile'!$G:$G,"High", 'BA Mobile'!$I:$I,"Triaged", 'BA Mobile'!$U:$U,"NO", 'BA Mobile'!$N:$N,"<"&$C$1+1, 'BA Mobile'!$N:$N,">="&$B$1 ) ) -> 0
